Workbook
Name Feriados: Parâmetros!$B$19:$B$33

Sheet WBS
A1: Nome da tarefa | B1: Duração | C1: Início | D1: Término | E1: Código EAP | F1: Tipo | G1: Predecessora | H1: Responsável (função) | I1: SIGCO | J1: Base do prazo
A2: PN 2027 – Instalação de Equipamentos Especiais (RL e RT) – 12 SIGCOs | B2: =D2-C2 | C2: =MIN(C3:C144) | D2: =MAX(D3:D144) | E2: 1 | F2: Projeto | H2: GP Sandro Padilha (DCMD)
A3: Gerenciamento do Projeto (PMBOK) | B3: =D3-C3 | C3: =MIN(C4:C8) | D3: =MAX(D4:D8) | E3: 1.1 | F3: Entrega | H3: GP / ASGP (PMO)
A4: Transfer Meeting – TM CAPEX (realizado) | B4: 0 | C4: 46301 | D4: =C4+B4 | E4: 1.1.1 | F4: Marco | H4: ASGP / ASPO | J4: Calendário PMO (ATA TM 06/10/2026)
A5: Kickoff Meeting – KOM CAPEX | B5: 0 | C5: 46324 | D5: =C5+B5 | E5: 1.1.2 | F5: Marco | H5: GP / PMO | J5: Calendário PMO (ATA TM 06/10/2026)
A6: Project Review Meeting – PRM CAPEX (consolidar planejamento / salvar linha de base) | B6: 0 | C6: 46358 | D6: =C6+B6 | E6: 1.1.3 | F6: Marco | H6: GP / PMO | J6: Calendário PMO (ATA TM 06/10/2026)
A7: Monitoramento e controle (FUM mensal, reports, forecast e gestão de riscos) | B7: =D7-C7 | C7: =D6 | D7: =MAX(D23,D34,D45,D56,D67,D78,D89,D100,D111,D122,D133,D144) | E7: 1.1.4 | F7: Pacote | G7: PRM | H7: GP | J7: Do PRM ao último Encerramento Contábil (duração derivada)
A8: Encerramento do projeto: Close Meeting (CM), termo de encerramento, lições aprendidas | B8: =D8-C8 | C8: =MAX(D23,D34,D45,D56,D67,D78,D89,D100,D111,D122,D133,D144) | D8: =Parâmetros!$B$16 | E8: 1.1.5 | F8: Pacote | G8: Último Enc. Contábil | H8: GP / PMO | J8: Após o último Encerramento Contábil (restrição: até 17/11/2027)
A9: Aquisições e Contratações | B9: =D9-C9 | C9: =MIN(C10:C11) | D9: =MAX(D10:D11) | E9: 1.2 | F9: Entrega | H9: DCMD / Suprimentos
A10: Equipamentos RL/RT disponíveis para a 1ª frente (PMA/RFP – data necessária em campo) | B10: 0 | C10: =MIN(C14,C25,C36,C47,C58,C69,C80,C91,C102,C113,C124,C135) | D10: =C10+B10 | E10: 1.2.1 | F10: Marco | H10: DCMD (PMA de materiais) | J10: Data necessária = início da 1ª execução (sem prazo de aquisição adotado: validar lead time com Suprimentos)
A11: Contratação da empreiteira executora (EPS) – O.S. assinada para a 1ª frente | B11: 0 | C11: =MIN(C14,C25,C36,C47,C58,C69,C80,C91,C102,C113,C124,C135) | D11: =C11+B11 | E11: 1.2.2 | F11: Marco | H11: DCMD (contratação de obras) | J11: Data necessária = início da 1ª execução (sem prazo de aquisição adotado: validar lead time com Suprimentos)
A12: Instalação, comissionamento e encerramento por SIGCO | B12: =D12-C12 | C12: =MIN(C13:C144) | D12: =MAX(D13:D144) | E12: 1.3 | F12: Entrega | H12: DCMD (COCM) / DEOP / DMSL
A13: Instalação de RL e RT - LD UHE Isamu - Ponte Alta - 1UI1 - QP (90811) | B13: =D13-C13 | C13: =MIN(C14:C23) | D13: =MAX(D14:D23) | E13: 1.3.1 | F13: Pacote | H13: GP Sandro Padilha | I13: 90811 | J13: 4 RL 34,5 kV + 3 RT 34,5 kV (+ 0,25 km RD MT e 2 chaves faca)
A14: Executar Obras | B14: =Parâmetros!$B$6 | C14: 46419 | D14: =C14+B14 | E14: 1.3.1.1 | F14: Atividade | G14: Início por meta de energização | H14: EPS (executora) / Supervisor de Obras DCMD | I14: 90811 | J14: PN 2026 – blocos RL/RT
A15: Obras Concluídas | B15: 0 | C15: =D14 | D15: =C15+B15 | E15: 1.3.1.2 | F15: Marco | G15: Executar Obras | H15: EPS | I15: 90811 | J15: Marco
A16: Fiscalização | B16: =Parâmetros!$B$7 | C16: =WORKDAY(D15,1,Feriados) | D16: =C16+B16 | E16: 1.3.1.3 | F16: Atividade | G16: Obras Concluídas | H16: Fiscalização de obras (Resulta) | I16: 90811 | J16: PN 2026 – blocos RL/RT
A17: Cadastro EO/ Integração parcial | B17: =Parâmetros!$B$8 | C17: =WORKDAY(D16,1,Feriados) | D17: =C17+B17 | E17: 1.3.1.4 | F17: Atividade | G17: Fiscalização | H17: DCMD (Cadastro EO/TS) | I17: 90811 | J17: PN 2026 – blocos RL/RT
A18: Entrega do TCI pela empreiteira / Integração final | B18: =Parâmetros!$B$9 | C18: =WORKDAY(D17,1,Feriados) | D18: =C18+B18 | E18: 1.3.1.5 | F18: Atividade | G18: Cadastro EO | H18: EPS / DCMD | I18: 90811 | J18: PN 2026 – blocos RL/RT
A19: Abertura de chamado/ Atendimento GAT | B19: =Parâmetros!$B$10 | C19: =C18 | D19: =C19+B19 | E19: 1.3.1.6 | F19: Atividade | G19: TCI (início) | H19: DCMD / GAT | I19: 90811 | J19: PN 2026 – blocos RL/RT
A20: Comissionar Equipamentos | B20: =Parâmetros!$B$11 | C20: =C18 | D20: =C20+B20 | E20: 1.3.1.7 | F20: Atividade | G20: TCI (início) | H20: DMSL / DEOP (ajuste de proteção) | I20: 90811 | J20: PN 2026 – blocos RL/RT
A21: Equipamentos em Operação | B21: 0 | C21: =D20 | D21: =C21+B21 | E21: 1.3.1.8 | F21: Marco | G21: Comissionar Equip. | H21: DMSL / DEOP | I21: 90811 | J21: Marco = término do comissionamento
A22: Encerramento Técnico | B22: =Parâmetros!$B$12 | C22: =WORKDAY(D21,1,Feriados) | D22: =WORKDAY(C22,B22,Feriados) | E22: 1.3.1.9 | F22: Atividade | G22: Equip. em Operação | H22: DCMD (Encerramento Técnico) | I22: 90811 | J22: PN 2026 – blocos RL/RT (dias úteis)
A23: Encerramento Contábil | B23: =Parâmetros!$B$13 | C23: =WORKDAY(D22,1,Feriados) | D23: =WORKDAY(C23,B23,Feriados) | E23: 1.3.1.10 | F23: Atividade | G23: Encerramento Técnico | H23: DCMD / Contabilidade | I23: 90811 | J23: PN 2026 – blocos RL/RT (dias úteis)
A24: Estudo de QS - LD Gurupi - Duere (91979) | B24: =D24-C24 | C24: =MIN(C25:C34) | D24: =MAX(D25:D34) | E24: 1.3.2 | F24: Pacote | H24: GP Sandro Padilha | I24: 91979 | J24: 1 RL rural 34,5 kV + 3 TripSaver
A25: Executar Obras | B25: =Parâmetros!$B$5 | C25: 46465 | D25: =C25+B25 | E25: 1.3.2.1 | F25: Atividade | G25: Início por meta de energização | H25: EPS (executora) / Supervisor de Obras DCMD | I25: 91979 | J25: PN 2026 – blocos RL/RT
A26: Obras Concluídas | B26: 0 | C26: =D25 | D26: =C26+B26 | E26: 1.3.2.2 | F26: Marco | G26: Executar Obras | H26: EPS | I26: 91979 | J26: Marco
A27: Fiscalização | B27: =Parâmetros!$B$7 | C27: =WORKDAY(D26,1,Feriados) | D27: =C27+B27 | E27: 1.3.2.3 | F27: Atividade | G27: Obras Concluídas | H27: Fiscalização de obras (Resulta) | I27: 91979 | J27: PN 2026 – blocos RL/RT
A28: Cadastro EO/ Integração parcial | B28: =Parâmetros!$B$8 | C28: =WORKDAY(D27,1,Feriados) | D28: =C28+B28 | E28: 1.3.2.4 | F28: Atividade | G28: Fiscalização | H28: DCMD (Cadastro EO/TS) | I28: 91979 | J28: PN 2026 – blocos RL/RT
A29: Entrega do TCI pela empreiteira / Integração final | B29: =Parâmetros!$B$9 | C29: =WORKDAY(D28,1,Feriados) | D29: =C29+B29 | E29: 1.3.2.5 | F29: Atividade | G29: Cadastro EO | H29: EPS / DCMD | I29: 91979 | J29: PN 2026 – blocos RL/RT
A30: Abertura de chamado/ Atendimento GAT | B30: =Parâmetros!$B$10 | C30: =C29 | D30: =C30+B30 | E30: 1.3.2.6 | F30: Atividade | G30: TCI (início) | H30: DCMD / GAT | I30: 91979 | J30: PN 2026 – blocos RL/RT
A31: Comissionar Equipamentos | B31: =Parâmetros!$B$11 | C31: =C29 | D31: =C31+B31 | E31: 1.3.2.7 | F31: Atividade | G31: TCI (início) | H31: DMSL / DEOP (ajuste de proteção) | I31: 91979 | J31: PN 2026 – blocos RL/RT
A32: Equipamentos em Operação | B32: 0 | C32: =D31 | D32: =C32+B32 | E32: 1.3.2.8 | F32: Marco | G32: Comissionar Equip. | H32: DMSL / DEOP | I32: 91979 | J32: Marco = término do comissionamento
A33: Encerramento Técnico | B33: =Parâmetros!$B$12 | C33: =WORKDAY(D32,1,Feriados) | D33: =WORKDAY(C33,B33,Feriados) | E33: 1.3.2.9 | F33: Atividade | G33: Equip. em Operação | H33: DCMD (Encerramento Técnico) | I33: 91979 | J33: PN 2026 – blocos RL/RT (dias úteis)
A34: Encerramento Contábil | B34: =Parâmetros!$B$13 | C34: =WORKDAY(D33,1,Feriados) | D34: =WORKDAY(C34,B34,Feriados) | E34: 1.3.2.10 | F34: Atividade | G34: Encerramento Técnico | H34: DCMD / Contabilidade | I34: 91979 | J34: PN 2026 – blocos RL/RT (dias úteis)
A35: Estudo de QS - 4 de Araguaína IV (92118) | B35: =D35-C35 | C35: =MIN(C36:C45) | D35: =MAX(D36:D45) | E35: 1.3.3 | F35: Pacote | H35: GP Sandro Padilha | I35: 92118 | J35: 1 RL automático 13,8 kV
A36: Executar Obras | B36: =Parâmetros!$B$5 | C36: 46465 | D36: =C36+B36 | E36: 1.3.3.1 | F36: Atividade | G36: Início por meta de energização | H36: EPS (executora) / Supervisor de Obras DCMD | I36: 92118 | J36: PN 2026 – blocos RL/RT
A37: Obras Concluídas | B37: 0 | C37: =D36 | D37: =C37+B37 | E37: 1.3.3.2 | F37: Marco | G37: Executar Obras | H37: EPS | I37: 92118 | J37: Marco
A38: Fiscalização | B38: =Parâmetros!$B$7 | C38: =WORKDAY(D37,1,Feriados) | D38: =C38+B38 | E38: 1.3.3.3 | F38: Atividade | G38: Obras Concluídas | H38: Fiscalização de obras (Resulta) | I38: 92118 | J38: PN 2026 – blocos RL/RT
A39: Cadastro EO/ Integração parcial | B39: =Parâmetros!$B$8 | C39: =WORKDAY(D38,1,Feriados) | D39: =C39+B39 | E39: 1.3.3.4 | F39: Atividade | G39: Fiscalização | H39: DCMD (Cadastro EO/TS) | I39: 92118 | J39: PN 2026 – blocos RL/RT
A40: Entrega do TCI pela empreiteira / Integração final | B40: =Parâmetros!$B$9 | C40: =WORKDAY(D39,1,Feriados) | D40: =C40+B40 | E40: 1.3.3.5 | F40: Atividade | G40: Cadastro EO | H40: EPS / DCMD | I40: 92118 | J40: PN 2026 – blocos RL/RT
...

Sheet Cronograma Macro
A1: Cronograma macro – PN 2027: instalação de RL e RT
A3: SIGCO | B3: Projeto | C3: Pacote | D3: Equip. | E3: Início da execução | F3: Obras concluídas | G3: Início comissionamento | H3: Equip. em operação | I3: Meta de energização | J3: Folga vs. meta (dias) | K3: Fim Enc. Técnico | L3: Fim Enc. Contábil | M3: Duração total (dias) | N3: Folga p/ limite contábil 17/11/2027 (dias)
A4: 90811 | B4: =Carteira!C4 | C4: =Carteira!I4 | D4: =Carteira!H4 | E4: =WBS!C14 | F4: =WBS!D15 | G4: =WBS!C20 | H4: =WBS!D21 | I4: =Carteira!J4 | J4: =I4-H4 | K4: =WBS!D22 | L4: =WBS!D23 | M4: =L4-E4 | N4: =Parâmetros!$B$16-L4
A5: 91979 | B5: =Carteira!C5 | C5: =Carteira!I5 | D5: =Carteira!H5 | E5: =WBS!C25 | F5: =WBS!D26 | G5: =WBS!C31 | H5: =WBS!D32 | I5: =Carteira!J5 | J5: =I5-H5 | K5: =WBS!D33 | L5: =WBS!D34 | M5: =L5-E5 | N5: =Parâmetros!$B$16-L5
A6: 92118 | B6: =Carteira!C6 | C6: =Carteira!I6 | D6: =Carteira!H6 | E6: =WBS!C36 | F6: =WBS!D37 | G6: =WBS!C42 | H6: =WBS!D43 | I6: =Carteira!J6 | J6: =I6-H6 | K6: =WBS!D44 | L6: =WBS!D45 | M6: =L6-E6 | N6: =Parâmetros!$B$16-L6
A7: 89267 | B7: =Carteira!C7 | C7: =Carteira!I7 | D7: =Carteira!H7 | E7: =WBS!C47 | F7: =WBS!D48 | G7: =WBS!C53 | H7: =WBS!D54 | I7: =Carteira!J7 | J7: =I7-H7 | K7: =WBS!D55 | L7: =WBS!D56 | M7: =L7-E7 | N7: =Parâmetros!$B$16-L7
A8: 92094 | B8: =Carteira!C8 | C8: =Carteira!I8 | D8: =Carteira!H8 | E8: =WBS!C58 | F8: =WBS!D59 | G8: =WBS!C64 | H8: =WBS!D65 | I8: =Carteira!J8 | J8: =I8-H8 | K8: =WBS!D66 | L8: =WBS!D67 | M8: =L8-E8 | N8: =Parâmetros!$B$16-L8
A9: 92095 | B9: =Carteira!C9 | C9: =Carteira!I9 | D9: =Carteira!H9 | E9: =WBS!C69 | F9: =WBS!D70 | G9: =WBS!C75 | H9: =WBS!D76 | I9: =Carteira!J9 | J9: =I9-H9 | K9: =WBS!D77 | L9: =WBS!D78 | M9: =L9-E9 | N9: =Parâmetros!$B$16-L9
A10: 92101 | B10: =Carteira!C10 | C10: =Carteira!I10 | D10: =Carteira!H10 | E10: =WBS!C80 | F10: =WBS!D81 | G10: =WBS!C86 | H10: =WBS!D87 | I10: =Carteira!J10 | J10: =I10-H10 | K10: =WBS!D88 | L10: =WBS!D89 | M10: =L10-E10 | N10: =Parâmetros!$B$16-L10
A11: 92102 | B11: =Carteira!C11 | C11: =Carteira!I11 | D11: =Carteira!H11 | E11: =WBS!C91 | F11: =WBS!D92 | G11: =WBS!C97 | H11: =WBS!D98 | I11: =Carteira!J11 | J11: =I11-H11 | K11: =WBS!D99 | L11: =WBS!D100 | M11: =L11-E11 | N11: =Parâmetros!$B$16-L11
A12: 70838 | B12: =Carteira!C12 | C12: =Carteira!I12 | D12: =Carteira!H12 | E12: =WBS!C102 | F12: =WBS!D103 | G12: =WBS!C108 | H12: =WBS!D109 | I12: =Carteira!J12 | J12: =I12-H12 | K12: =WBS!D110 | L12: =WBS!D111 | M12: =L12-E12 | N12: =Parâmetros!$B$16-L12
A13: 70978 | B13: =Carteira!C13 | C13: =Carteira!I13 | D13: =Carteira!H13 | E13: =WBS!C113 | F13: =WBS!D114 | G13: =WBS!C119 | H13: =WBS!D120 | I13: =Carteira!J13 | J13: =I13-H13 | K13: =WBS!D121 | L13: =WBS!D122 | M13: =L13-E13 | N13: =Parâmetros!$B$16-L13
A14: 89249 | B14: =Carteira!C14 | C14: =Carteira!I14 | D14: =Carteira!H14 | E14: =WBS!C124 | F14: =WBS!D125 | G14: =WBS!C130 | H14: =WBS!D131 | I14: =Carteira!J14 | J14: =I14-H14 | K14: =WBS!D132 | L14: =WBS!D133 | M14: =L14-E14 | N14: =Parâmetros!$B$16-L14
A15: 89307 | B15: =Carteira!C15 | C15: =Carteira!I15 | D15: =Carteira!H15 | E15: =WBS!C135 | F15: =WBS!D136 | G15: =WBS!C141 | H15: =WBS!D142 | I15: =Carteira!J15 | J15: =I15-H15 | K15: =WBS!D143 | L15: =WBS!D144 | M15: =L15-E15 | N15: =Parâmetros!$B$16-L15
A17: Equipamentos em operação ≤ meta de energização do mês (TM 06/10/2026). Folga = 0 indica cronograma sem reserva (agosto/2027).

Sheet Gantt
A1: Gantt semanal – PN 2027 (barras recalculam com as datas da aba WBS)
E2: Legenda: | F2: Execução | O2: Fiscalização / Cadastro / TCI | X2: GAT / Comissionamento | AG2: Encerramento | AP2: Marco
F3: 09/26 | G3: 10/26 | K3: 11/26 | P3: 12/26 | T3: 01/27 | X3: 02/27 | AB3: 03/27 | AG3: 04/27 | AK3: 05/27 | AP3: 06/27 | AT3: 07/27 | AX3: 08/27 | BC3: 09/27 | BG3: 10/27 | BK3: 11/27
A4: Código EAP | B4: Tarefa | C4: Início | D4: Término | E4: tipo | F4: 46293 | G4: 46300 | H4: 46307 | I4: 46314 | J4: 46321 | K4: 46328 | L4: 46335 | M4: 46342 | N4: 46349 | O4: 46356 | P4: 46363 | Q4: 46370 | R4: 46377 | S4: 46384 | T4: 46391 | U4: 46398 | V4: 46405 | W4: 46412 | X4: 46419 | Y4: 46426 | Z4: 46433 | AA4: 46440 | AB4: 46447 | AC4: 46454 | AD4: 46461 | AE4: 46468 | AF4: 46475 | AG4: 46482 | AH4: 46489 | AI4: 46496 | AJ4: 46503 | AK4: 46510 | AL4: 46517 | AM4: 46524 | AN4: 46531 | AO4: 46538 | AP4: 46545 | AQ4: 46552 | AR4: 46559 | AS4: 46566 | AT4: 46573 | AU4: 46580 | AV4: 46587 | AW4: 46594 | AX4: 46601 | AY4: 46608 | AZ4: 46615 | BA4: 46622 | BB4: 46629 | BC4: 46636 | BD4: 46643 | BE4: 46650 | BF4: 46657 | BG4: 46664 | BH4: 46671 | BI4: 46678 | BJ4: 46685 | BK4: 46692 | BL4: 46699 | BM4: 46706 | BN4: 46713
A5: =WBS!E2 | B5: =WBS!A2 | C5: =WBS!C2 | D5: =WBS!D2 | E5: sum
A6: =WBS!E3 | B6: =WBS!A3 | C6: =WBS!C3 | D6: =WBS!D3 | E6: sum
A7: =WBS!E4 | B7: =WBS!A4 | C7: =WBS!C4 | D7: =WBS!D4 | E7: ms
A8: =WBS!E5 | B8: =WBS!A5 | C8: =WBS!C5 | D8: =WBS!D5 | E8: ms
A9: =WBS!E6 | B9: =WBS!A6 | C9: =WBS!C6 | D9: =WBS!D6 | E9: ms
A10: =WBS!E7 | B10: =WBS!A7 | C10: =WBS!C7 | D10: =WBS!D7 | E10: sum
A11: =WBS!E8 | B11: =WBS!A8 | C11: =WBS!C8 | D11: =WBS!D8 | E11: sum
A12: =WBS!E9 | B12: =WBS!A9 | C12: =WBS!C9 | D12: =WBS!D9 | E12: sum
A13: =WBS!E10 | B13: =WBS!A10 | C13: =WBS!C10 | D13: =WBS!D10 | E13: ms
A14: =WBS!E11 | B14: =WBS!A11 | C14: =WBS!C11 | D14: =WBS!D11 | E14: ms
A15: =WBS!E12 | B15: =WBS!A12 | C15: =WBS!C12 | D15: =WBS!D12 | E15: sum
A16: =WBS!E13 | B16: =WBS!A13 | C16: =WBS!C13 | D16: =WBS!D13 | E16: sum
... A147: =WBS!E144 | B147: =WBS!A144 | C147: =WBS!C144 | D147: =WBS!D144 | E147: enc
B149: Coluna rosada = semana do limite de encerramento contábil (17/11/2027).

Sheet Curva orçamentária
A1: Curva orçamentária 2027 alinhada à WBS (R$) – proposta para atualização do SIACO
A2: Material no mês de início da execução (parâmetro 60%) e serviço rateado pelos dias de execução. Total = Orçamento 08.10 (aprovado). O cadastro 08.10 distribui o valor linearmente de jan a dez; como no KOM 2026, recomenda-se ajustar o SIACO para coincidir com a curva da WBS.
A4: SIGCO | B4: Projeto | C4: Total aprovado (08.10) | D4: Jan | E4: Fev | F4: Mar | G4: Abr | H4: Mai | I4: Jun | J4: Jul | K4: Ago | L4: Set | M4: Out | N4: Nov | O4: Dez | P4: Total curva | Q4: Check (Σ = total)
A5: 90811 | B5: =Carteira!C4 | C5: =Carteira!L4 | D5: =$C5*(Parâmetros!$B$15*(YEAR(WBS!$C$14)=2027)*(MONTH(WBS!$C$14)=1)+(1-Parâmetros!$B$15)*MAX(0,MIN(WBS!$D$14,EDATE(DATE(2027,1,1),1))-MAX(WBS!$C$14,DATE(2027,1,1)))/WBS!$B$14) | E5: =$C5*(Parâmetros!$B$15*(YEAR(WBS!$C$14)=2027)*(MONTH(WBS!$C$14)=2)+(1-Parâmetros!$B$15)*MAX(0,MIN(WBS!$D$14,EDATE(DATE(2027,2,1),1))-MAX(WBS!$C$14,DATE(2027,2,1)))/WBS!$B$14) | F5: =$C5*(Parâmetros!$B$15*(YEAR(WBS!$C$14)=2027)*(MONTH(WBS!$C$14)=3)+(1-Parâmetros!$B$15)*MAX(0,MIN(WBS!$D$14,EDATE(DATE(2027,3,1),1))-MAX(WBS!$C$14,DATE(2027,3,1)))/WBS!$B$14) | G5: =$C5*(Parâmetros!$B$15*(YEAR(WBS!$C$14)=2027)*(MONTH(WBS!$C$14)=4)+(1-Parâmetros!$B$15)*MAX(0,MIN(WBS!$D$14,EDATE(DATE(2027,4,1),1))-MAX(WBS!$C$14,DATE(2027,4,1)))/WBS!$B$14) | H5: =$C5*(Parâmetros!$B$15*(YEAR(WBS!$C$14)=2027)*(MONTH(WBS!$C$14)=5)+(1-Parâmetros!$B$15)*MAX(0,MIN(WBS!$D$14,EDATE(DATE(2027,5,1),1))-MAX(WBS!$C$14,DATE(2027,5,1)))/WBS!$B$14) | I5: =$C5*(Parâmetros!$B$15*(YEAR(WBS!$C$14)=2027)*(MONTH(WBS!$C$14)=6)+(1-Parâmetros!$B$15)*MAX(0,MIN(WBS!$D$14,EDATE(DATE(2027,6,1),1))-MAX(WBS!$C$14,DATE(2027,6,1)))/WBS!$B$14) | J5: =$C5*(Parâmetros!$B$15*(YEAR(WBS!$C$14)=2027)*(MONTH(WBS!$C$14)=7)+(1-Parâmetros!$B$15)*MAX(0,MIN(WBS!$D$14,EDATE(DATE(2027,7,1),1))-MAX(WBS!$C$14,DATE(2027,7,1)))/WBS!$B$14) | K5: =$C5*(Parâmetros!$B$15*(YEAR(WBS!$C$14)=2027)*(MONTH(WBS!$C$14)=8)+(1-Parâmetros!$B$15)*MAX(0,MIN(WBS!$D$14,EDATE(DATE(2027,8,1),1))-MAX(WBS!$C$14,DATE(2027,8,1)))/WBS!$B$14) | L5: =$C5*(Parâmetros!$B$15*(YEAR(WBS!$C$14)=2027)*(MONTH(WBS!$C$14)=9)+(1-Parâmetros!$B$15)*MAX(0,MIN(WBS!$D$14,EDATE(DATE(2027,9,1),1))-MAX(WBS!$C$14,DATE(2027,9,1)))/WBS!$B$14) | M5: =$C5*(Parâmetros!$B$15*(YEAR(WBS!$C$14)=2027)*(MONTH(WBS!$C$14)=10)+(1-Parâmetros!$B$15)*MAX(0,MIN(WBS!$D$14,EDATE(DATE(2027,10,1),1))-MAX(WBS!$C$14,DATE(2027,10,1)))/WBS!$B$14) | N5: =$C5*(Parâmetros!$B$15*(YEAR(WBS!$C$14)=2027)*(MONTH(WBS!$C$14)=11)+(1-Parâmetros!$B$15)*MAX(0,MIN(WBS!$D$14,EDATE(DATE(2027,11,1),1))-MAX(WBS!$C$14,DATE(2027,11,1)))/WBS!$B$14) | O5: =$C5*(Parâmetros!$B$15*(YEAR(WBS!$C$14)=2027)*(MONTH(WBS!$C$14)=12)+(1-Parâmetros!$B$15)*MAX(0,MIN(WBS!$D$14,EDATE(DATE(2027,12,1),1))-MAX(WBS!$C$14,DATE(2027,12,1)))/WBS!$B$14) | P5: =SUM(D5:O5) | Q5: =IF(ABS(P5-C5)<0.5,"ok","DIVERGE")
A6: 91979 | B6: =Carteira!C5 | C6: =Carteira!L5 | D6: =$C6*(Parâmetros!$B$15*(YEAR(WBS!$C$25)=2027)*(MONTH(WBS!$C$25)=1)+(1-Parâmetros!$B$15)*MAX(0,MIN(WBS!$D$25,EDATE(DATE(2027,1,1),1))-MAX(WBS!$C$25,DATE(2027,1,1)))/WBS!$B$25) | E6: =$C6*(Parâmetros!$B$15*(YEAR(WBS!$C$25)=2027)*(MONTH(WBS!$C$25)=2)+(1-Parâmetros!$B$15)*MAX(0,MIN(WBS!$D$25,EDATE(DATE(2027,2,1),1))-MAX(WBS!$C$25,DATE(2027,2,1)))/WBS!$B$25) | F6: =$C6*(Parâmetros!$B$15*(YEAR(WBS!$C$25)=2027)*(MONTH(WBS!$C$25)=3)+(1-Parâmetros!$B$15)*MAX(0,MIN(WBS!$D$25,EDATE(DATE(2027,3,1),1))-MAX(WBS!$C$25,DATE(2027,3,1)))/WBS!$B$25) | G6: =$C6*(Parâmetros!$B$15*(YEAR(WBS!$C$25)=2027)*(MONTH(WBS!$C$25)=4)+(1-Parâmetros!$B$15)*MAX(0,MIN(WBS!$D$25,EDATE(DATE(2027,4,1),1))-MAX(WBS!$C$25,DATE(2027,4,1)))/WBS!$B$25) | H6: =$C6*(Parâmetros!$B$15*(YEAR(WBS!$C$25)=2027)*(MONTH(WBS!$C$25)=5)+(1-Parâmetros!$B$15)*MAX(0,MIN(WBS!$D$25,EDATE(DATE(2027,5,1),1))-MAX(WBS!$C$25,DATE(2027,5,1)))/WBS!$B$25) | I6: =$C6*(Parâmetros!$B$15*(YEAR(WBS!$C$25)=2027)*(MONTH(WBS!$C$25)=6)+(1-Parâmetros!$B$15)*MAX(0,MIN(WBS!$D$25,EDATE(DATE(2027,6,1),1))-MAX(WBS!$C$25,DATE(2027,6,1)))/WBS!$B$25) | J6: =$C6*(Parâmetros!$B$15*(YEAR(WBS!$C$25)=2027)*(MONTH(WBS!$C$25)=7)+(1-Parâmetros!$B$15)*MAX(0,MIN(WBS!$D$25,EDATE(DATE(2027,7,1),1))-MAX(WBS!$C$25,DATE(2027,7,1)))/WBS!$B$25) | K6: =$C6*(Parâmetros!$B$15*(YEAR(WBS!$C$25)=2027)*(MONTH(WBS!$C$25)=8)+(1-Parâmetros!$B$15)*MAX(0,MIN(WBS!$D$25,EDATE(DATE(2027,8,1),1))-MAX(WBS!$C$25,DATE(2027,8,1)))/WBS!$B$25) | L6: =$C6*(Parâmetros!$B$15*(YEAR(WBS!$C$25)=2027)*(MONTH(WBS!$C$25)=9)+(1-Parâmetros!$B$15)*MAX(0,MIN(WBS!$D$25,EDATE(DATE(2027,9,1),1))-MAX(WBS!$C$25,DATE(2027,9,1)))/WBS!$B$25) | M6: =$C6*(Parâmetros!$B$15*(YEAR(WBS!$C$25)=2027)*(MONTH(WBS!$C$25)=10)+(1-Parâmetros!$B$15)*MAX(0,MIN(WBS!$D$25,EDATE(DATE(2027,10,1),1))-MAX(WBS!$C$25,DATE(2027,10,1)))/WBS!$B$25) | N6: =$C6*(Parâmetros!$B$15*(YEAR(WBS!$C$25)=2027)*(MONTH(WBS!$C$25)=11)+(1-Parâmetros!$B$15)*MAX(0,MIN(WBS!$D$25,EDATE(DATE(2027,11,1),1))-MAX(WBS!$C$25,DATE(2027,11,1)))/WBS!$B$25) | O6: =$C6*(Parâmetros!$B$15*(YEAR(WBS!$C$25)=2027)*(MONTH(WBS!$C$25)=12)+(1-Parâmetros!$B$15)*MAX(0,MIN(WBS!$D$25,EDATE(DATE(2027,12,1),1))-MAX(WBS!$C$25,DATE(2027,12,1)))/WBS!$B$25) | P6: =SUM(D6:O6) | Q6: =IF(ABS(P6-C6)<0.5,"ok","DIVERGE")
A7: 92118 | B7: =Carteira!C6 | C7: =Carteira!L6 | D7: =$C7*(Parâmetros!$B$15*(YEAR(WBS!$C$36)=2027)*(MONTH(WBS!$C$36)=1)+(1-Parâmetros!$B$15)*MAX(0,MIN(WBS!$D$36,EDATE(DATE(2027,1,1),1))-MAX(WBS!$C$36,DATE(2027,1,1)))/WBS!$B$36) | E7: =$C7*(Parâmetros!$B$15*(YEAR(WBS!$C$36)=2027)*(MONTH(WBS!$C$36)=2)+(1-Parâmetros!$B$15)*MAX(0,MIN(WBS!$D$36,EDATE(DATE(2027,2,1),1))-MAX(WBS!$C$36,DATE(2027,2,1)))/WBS!$B$36) | F7: =$C7*(Parâmetros!$B$15*(YEAR(WBS!$C$36)=2027)*(MONTH(WBS!$C$36)=3)+(1-Parâmetros!$B$15)*MAX(0,MIN(WBS!$D$36,EDATE(DATE(2027,3,1),1))-MAX(WBS!$C$36,DATE(2027,3,1)))/WBS!$B$36) | G7: =$C7*(Parâmetros!$B$15*(YEAR(WBS!$C$36)=2027)*(MONTH(WBS!$C$36)=4)+(1-Parâmetros!$B$15)*MAX(0,MIN(WBS!$D$36,EDATE(DATE(2027,4,1),1))-MAX(WBS!$C$36,DATE(2027,4,1)))/WBS!$B$36) | H7: =$C7*(Parâmetros!$B$15*(YEAR(WBS!$C$36)=2027)*(MONTH(WBS!$C$36)=5)+(1-Parâmetros!$B$15)*MAX(0,MIN(WBS!$D$36,EDATE(DATE(2027,5,1),1))-MAX(WBS!$C$36,DATE(2027,5,1)))/WBS!$B$36) | I7: =$C7*(Parâmetros!$B$15*(YEAR(WBS!$C$36)=2027)*(MONTH(WBS!$C$36)=6)+(1-Parâmetros!$B$15)*MAX(0,MIN(WBS!$D$36,EDATE(DATE(2027,6,1),1))-MAX(WBS!$C$36,DATE(2027,6,1)))/WBS!$B$36) | J7: =$C7*(Parâmetros!$B$15*(YEAR(WBS!$C$36)=2027)*(MONTH(WBS!$C$36)=7)+(1-Parâmetros!$B$15)*MAX(0,MIN(WBS!$D$36,EDATE(DATE(2027,7,1),1))-MAX(WBS!$C$36,DATE(2027,7,1)))/WBS!$B$36) | K7: =$C7*(Parâmetros!$B$15*(YEAR(WBS!$C$36)=2027)*(MONTH(WBS!$C$36)=8)+(1-Parâmetros!$B$15)*MAX(0,MIN(WBS!$D$36,EDATE(DATE(2027,8,1),1))-MAX(WBS!$C$36,DATE(2027,8,1)))/WBS!$B$36) | L7: =$C7*(Parâmetros!$B$15*(YEAR(WBS!$C$36)=2027)*(MONTH(WBS!$C$36)=9)+(1-Parâmetros!$B$15)*MAX(0,MIN(WBS!$D$36,EDATE(DATE(2027,9,1),1))-MAX(WBS!$C$36,DATE(2027,9,1)))/WBS!$B$36) | M7: =$C7*(Parâmetros!$B$15*(YEAR(WBS!$C$36)=2027)*(MONTH(WBS!$C$36)=10)+(1-Parâmetros!$B$15)*MAX(0,MIN(WBS!$D$36,EDATE(DATE(2027,10,1),1))-MAX(WBS!$C$36,DATE(2027,10,1)))/WBS!$B$36) | N7: =$C7*(Parâmetros!$B$15*(YEAR(WBS!$C$36)=2027)*(MONTH(WBS!$C$36)=11)+(1-Parâmetros!$B$15)*MAX(0,MIN(WBS!$D$36,EDATE(DATE(2027,11,1),1))-MAX(WBS!$C$36,DATE(2027,11,1)))/WBS!$B$36) | O7: =$C7*(Parâmetros!$B$15*(YEAR(WBS!$C$36)=2027)*(MONTH(WBS!$C$36)=12)+(1-Parâmetros!$B$15)*MAX(0,MIN(WBS!$D$36,EDATE(DATE(2027,12,1),1))-MAX(WBS!$C$36,DATE(2027,12,1)))/WBS!$B$36) | P7: =SUM(D7:O7) | Q7: =IF(ABS(P7-C7)<0.5,"ok","DIVERGE")
A8: 89267 | B8: =Carteira!C7 | C8: =Carteira!L7 | D8: =$C8*(Parâmetros!$B$15*(YEAR(WBS!$C$47)=2027)*(MONTH(WBS!$C$47)=1)+(1-Parâmetros!$B$15)*MAX(0,MIN(WBS!$D$47,EDATE(DATE(2027,1,1),1))-MAX(WBS!$C$47,DATE(2027,1,1)))/WBS!$B$47) | E8: =$C8*(Parâmetros!$B$15*(YEAR(WBS!$C$47)=2027)*(MONTH(WBS!$C$47)=2)+(1-Parâmetros!$B$15)*MAX(0,MIN(WBS!$D$47,EDATE(DATE(2027,2,1),1))-MAX(WBS!$C$47,DATE(2027,2,1)))/WBS!$B$47) | F8: =$C8*(Parâmetros!$B$15*(YEAR(WBS!$C$47)=2027)*(MONTH(WBS!$C$47)=3)+(1-Parâmetros!$B$15)*MAX(0,MIN(WBS!$D$47,EDATE(DATE(2027,3,1),1))-MAX(WBS!$C$47,DATE(2027,3,1)))/WBS!$B$47) | G8: =$C8*(Parâmetros!$B$15*(YEAR(WBS!$C$47)=2027)*(MONTH(WBS!$C$47)=4)+(1-Parâmetros!$B$15)*MAX(0,MIN(WBS!$D$47,EDATE(DATE(2027,4,1),1))-MAX(WBS!$C$47,DATE(2027,4,1)))/WBS!$B$47) | H8: =$C8*(Parâmetros!$B$15*(YEAR(WBS!$C$47)=2027)*(MONTH(WBS!$C$47)=5)+(1-Parâmetros!$B$15)*MAX(0,MIN(WBS!$D$47,EDATE(DATE(2027,5,1),1))-MAX(WBS!$C$47,DATE(2027,5,1)))/WBS!$B$47) | I8: =$C8*(Parâmetros!$B$15*(YEAR(WBS!$C$47)=2027)*(MONTH(WBS!$C$47)=6)+(1-Parâmetros!$B$15)*MAX(0,MIN(WBS!$D$47,EDATE(DATE(2027,6,1),1))-MAX(WBS!$C$47,DATE(2027,6,1)))/WBS!$B$47) | J8: =$C8*(Parâmetros!$B$15*(YEAR(WBS!$C$47)=2027)*(MONTH(WBS!$C$47)=7)+(1-Parâmetros!$B$15)*MAX(0,MIN(WBS!$D$47,EDATE(DATE(2027,7,1),1))-MAX(WBS!$C$47,DATE(2027,7,1)))/WBS!$B$47) | K8: =$C8*(Parâmetros!$B$15*(YEAR(WBS!$C$47)=2027)*(MONTH(WBS!$C$47)=8)+(1-Parâmetros!$B$15)*MAX(0,MIN(WBS!$D$47,EDATE(DATE(2027,8,1),1))-MAX(WBS!$C$47,DATE(2027,8,1)))/WBS!$B$47) | L8: =$C8*(Parâmetros!$B$15*(YEAR(WBS!$C$47)=2027)*(MONTH(WBS!$C$47)=9)+(1-Parâmetros!$B$15)*MAX(0,MIN(WBS!$D$47,EDATE(DATE(2027,9,1),1))-MAX(WBS!$C$47,DATE(2027,9,1)))/WBS!$B$47) | M8: =$C8*(Parâmetros!$B$15*(YEAR(WBS!$C$47)=2027)*(MONTH(WBS!$C$47)=10)+(1-Parâmetros!$B$15)*MAX(0,MIN(WBS!$D$47,EDATE(DATE(2027,10,1),1))-MAX(WBS!$C$47,DATE(2027,10,1)))/WBS!$B$47) | N8: =$C8*(Parâmetros!$B$15*(YEAR(WBS!$C$47)=2027)*(MONTH(WBS!$C$47)=11)+(1-Parâmetros!$B$15)*MAX(0,MIN(WBS!$D$47,EDATE(DATE(2027,11,1),1))-MAX(WBS!$C$47,DATE(2027,11,1)))/WBS!$B$47) | O8: =$C8*(Parâmetros!$B$15*(YEAR(WBS!$C$47)=2027)*(MONTH(WBS!$C$47)=12)+(1-Parâmetros!$B$15)*MAX(0,MIN(WBS!$D$47,EDATE(DATE(2027,12,1),1))-MAX(WBS!$C$47,DATE(2027,12,1)))/WBS!$B$47) | P8: =SUM(D8:O8) | Q8: =IF(ABS(P8-C8)<0.5,"ok","DIVERGE")
A9: 92094 | B9: =Carteira!C8 | C9: =Carteira!L8 | D9: =$C9*(Parâmetros!$B$15*(YEAR(WBS!$C$58)=2027)*(MONTH(WBS!$C$58)=1)+(1-Parâmetros!$B$15)*MAX(0,MIN(WBS!$D$58,EDATE(DATE(2027,1,1),1))-MAX(WBS!$C$58,DATE(2027,1,1)))/WBS!$B$58) | E9: =$C9*(Parâmetros!$B$15*(YEAR(WBS!$C$58)=2027)*(MONTH(WBS!$C$58)=2)+(1-Parâmetros!$B$15)*MAX(0,MIN(WBS!$D$58,EDATE(DATE(2027,2,1),1))-MAX(WBS!$C$58,DATE(2027,2,1)))/WBS!$B$58) | F9: =$C9*(Parâmetros!$B$15*(YEAR(WBS!$C$58)=2027)*(MONTH(WBS!$C$58)=3)+(1-Parâmetros!$B$15)*MAX(0,MIN(WBS!$D$58,EDATE(DATE(2027,3,1),1))-MAX(WBS!$C$58,DATE(2027,3,1)))/WBS!$B$58) | G9: =$C9*(Parâmetros!$B$15*(YEAR(WBS!$C$58)=2027)*(MONTH(WBS!$C$58)=4)+(1-Parâmetros!$B$15)*MAX(0,MIN(WBS!$D$58,EDATE(DATE(2027,4,1),1))-MAX(WBS!$C$58,DATE(2027,4,1)))/WBS!$B$58) | H9: =$C9*(Parâmetros!$B$15*(YEAR(WBS!$C$58)=2027)*(MONTH(WBS!$C$58)=5)+(1-Parâmetros!$B$15)*MAX(0,MIN(WBS!$D$58,EDATE(DATE(2027,5,1),1))-MAX(WBS!$C$58,DATE(2027,5,1)))/WBS!$B$58) | I9: =$C9*(Parâmetros!$B$15*(YEAR(WBS!$C$58)=2027)*(MONTH(WBS!$C$58)=6)+(1-Parâmetros!$B$15)*MAX(0,MIN(WBS!$D$58,EDATE(DATE(2027,6,1),1))-MAX(WBS!$C$58,DATE(2027,6,1)))/WBS!$B$58) | J9: =$C9*(Parâmetros!$B$15*(YEAR(WBS!$C$58)=2027)*(MONTH(WBS!$C$58)=7)+(1-Parâmetros!$B$15)*MAX(0,MIN(WBS!$D$58,EDATE(DATE(2027,7,1),1))-MAX(WBS!$C$58,DATE(2027,7,1)))/WBS!$B$58) | K9: =$C9*(Parâmetros!$B$15*(YEAR(WBS!$C$58)=2027)*(MONTH(WBS!$C$58)=8)+(1-Parâmetros!$B$15)*MAX(0,MIN(WBS!$D$58,EDATE(DATE(2027,8,1),1))-MAX(WBS!$C$58,DATE(2027,8,1)))/WBS!$B$58) | L9: =$C9*(Parâmetros!$B$15*(YEAR(WBS!$C$58)=2027)*(MONTH(WBS!$C$58)=9)+(1-Parâmetros!$B$15)*MAX(0,MIN(WBS!$D$58,EDATE(DATE(2027,9,1),1))-MAX(WBS!$C$58,DATE(2027,9,1)))/WBS!$B$58) | M9: =$C9*(Parâmetros!$B$15*(YEAR(WBS!$C$58)=2027)*(MONTH(WBS!$C$58)=10)+(1-Parâmetros!$B$15)*MAX(0,MIN(WBS!$D$58,EDATE(DATE(2027,10,1),1))-MAX(WBS!$C$58,DATE(2027,10,1)))/WBS!$B$58) | N9: =$C9*(Parâmetros!$B$15*(YEAR(WBS!$C$58)=2027)*(MONTH(WBS!$C$58)=11)+(1-Parâmetros!$B$15)*MAX(0,MIN(WBS!$D$58,EDATE(DATE(2027,11,1),1))-MAX(WBS!$C$58,DATE(2027,11,1)))/WBS!$B$58) | O9: =$C9*(Parâmetros!$B$15*(YEAR(WBS!$C$58)=2027)*(MONTH(WBS!$C$58)=12)+(1-Parâmetros!$B$15)*MAX(0,MIN(WBS!$D$58,EDATE(DATE(2027,12,1),1))-MAX(WBS!$C$58,DATE(2027,12,1)))/WBS!$B$58) | P9: =SUM(D9:O9) | Q9: =IF(ABS(P9-C9)<0.5,"ok","DIVERGE")
A10: 92095 | B10: =Carteira!C9 | C10: =Carteira!L9 | D10: =$C10*(Parâmetros!$B$15*(YEAR(WBS!$C$69)=2027)*(MONTH(WBS!$C$69)=1)+(1-Parâmetros!$B$15)*MAX(0,MIN(WBS!$D$69,EDATE(DATE(2027,1,1),1))-MAX(WBS!$C$69,DATE(2027,1,1)))/WBS!$B$69) | E10: =$C10*(Parâmetros!$B$15*(YEAR(WBS!$C$69)=2027)*(MONTH(WBS!$C$69)=2)+(1-Parâmetros!$B$15)*MAX(0,MIN(WBS!$D$69,EDATE(DATE(2027,2,1),1))-MAX(WBS!$C$69,DATE(2027,2,1)))/WBS!$B$69) | F10: =$C10*(Parâmetros!$B$15*(YEAR(WBS!$C$69)=2027)*(MONTH(WBS!$C$69)=3)+(1-Parâmetros!$B$15)*MAX(0,MIN(WBS!$D$69,EDATE(DATE(2027,3,1),1))-MAX(WBS!$C$69,DATE(2027,3,1)))/WBS!$B$69) | G10: =$C10*(Parâmetros!$B$15*(YEAR(WBS!$C$69)=2027)*(MONTH(WBS!$C$69)=4)+(1-Parâmetros!$B$15)*MAX(0,MIN(WBS!$D$69,EDATE(DATE(2027,4,1),1))-MAX(WBS!$C$69,DATE(2027,4,1)))/WBS!$B$69) | H10: =$C10*(Parâmetros!$B$15*(YEAR(WBS!$C$69)=2027)*(MONTH(WBS!$C$69)=5)+(1-Parâmetros!$B$15)*MAX(0,MIN(WBS!$D$69,EDATE(DATE(2027,5,1),1))-MAX(WBS!$C$69,DATE(2027,5,1)))/WBS!$B$69) | I10: =$C10*(Parâmetros!$B$15*(YEAR(WBS!$C$69)=2027)*(MONTH(WBS!$C$69)=6)+(1-Parâmetros!$B$15)*MAX(0,MIN(WBS!$D$69,EDATE(DATE(2027,6,1),1))-MAX(WBS!$C$69,DATE(2027,6,1)))/WBS!$B$69) | J10: =$C10*(Parâmetros!$B$15*(YEAR(WBS!$C$69)=2027)*(MONTH(WBS!$C$69)=7)+(1-Parâmetros!$B$15)*MAX(0,MIN(WBS!$D$69,EDATE(DATE(2027,7,1),1))-MAX(WBS!$C$69,DATE(2027,7,1)))/WBS!$B$69) | K10: =$C10*(Parâmetros!$B$15*(YEAR(WBS!$C$69)=2027)*(MONTH(WBS!$C$69)=8)+(1-Parâmetros!$B$15)*MAX(0,MIN(WBS!$D$69,EDATE(DATE(2027,8,1),1))-MAX(WBS!$C$69,DATE(2027,8,1)))/WBS!$B$69) | L10: =$C10*(Parâmetros!$B$15*(YEAR(WBS!$C$69)=2027)*(MONTH(WBS!$C$69)=9)+(1-Parâmetros!$B$15)*MAX(0,MIN(WBS!$D$69,EDATE(DATE(2027,9,1),1))-MAX(WBS!$C$69,DATE(2027,9,1)))/WBS!$B$69) | M10: =$C10*(Parâmetros!$B$15*(YEAR(WBS!$C$69)=2027)*(MONTH(WBS!$C$69)=10)+(1-Parâmetros!$B$15)*MAX(0,MIN(WBS!$D$69,EDATE(DATE(2027,10,1),1))-MAX(WBS!$C$69,DATE(2027,10,1)))/WBS!$B$69) | N10: =$C10*(Parâmetros!$B$15*(YEAR(WBS!$C$69)=2027)*(MONTH(WBS!$C$69)=11)+(1-Parâmetros!$B$15)*MAX(0,MIN(WBS!$D$69,EDATE(DATE(2027,11,1),1))-MAX(WBS!$C$69,DATE(2027,11,1)))/WBS!$B$69) | O10: =$C10*(Parâmetros!$B$15*(YEAR(WBS!$C$69)=2027)*(MONTH(WBS!$C$69)=12)+(1-Parâmetros!$B$15)*MAX(0,MIN(WBS!$D$69,EDATE(DATE(2027,12,1),1))-MAX(WBS!$C$69,DATE(2027,12,1)))/WBS!$B$69) | P10: =SUM(D10:O10) | Q10: =IF(ABS(P10-C10)<0.5,"ok","DIVERGE")
A11: 92101 | B11: =Carteira!C10 | C11: =Carteira!L10 | D11: =$C11*(Parâmetros!$B$15*(YEAR(WBS!$C$80)=2027)*(MONTH(WBS!$C$80)=1)+(1-Parâmetros!$B$15)*MAX(0,MIN(WBS!$D$80,EDATE(DATE(2027,1,1),1))-MAX(WBS!$C$80,DATE(2027,1,1)))/WBS!$B$80) | E11: =$C11*(Parâmetros!$B$15*(YEAR(WBS!$C$80)=2027)*(MONTH(WBS!$C$80)=2)+(1-Parâmetros!$B$15)*MAX(0,MIN(WBS!$D$80,EDATE(DATE(2027,2,1),1))-MAX(WBS!$C$80,DATE(2027,2,1)))/WBS!$B$80) | F11: =$C11*(Parâmetros!$B$15*(YEAR(WBS!$C$80)=2027)*(MONTH(WBS!$C$80)=3)+(1-Parâmetros!$B$15)*MAX(0,MIN(WBS!$D$80,EDATE(DATE(2027,3,1),1))-MAX(WBS!$C$80,DATE(2027,3,1)))/WBS!$B$80) | G11: =$C11*(Parâmetros!$B$15*(YEAR(WBS!$C$80)=2027)*(MONTH(WBS!$C$80)=4)+(1-Parâmetros!$B$15)*MAX(0,MIN(WBS!$D$80,EDATE(DATE(2027,4,1),1))-MAX(WBS!$C$80,DATE(2027,4,1)))/WBS!$B$80) | H11: =$C11*(Parâmetros!$B$15*(YEAR(WBS!$C$80)=2027)*(MONTH(WBS!$C$80)=5)+(1-Parâmetros!$B$15)*MAX(0,MIN(WBS!$D$80,EDATE(DATE(2027,5,1),1))-MAX(WBS!$C$80,DATE(2027,5,1)))/WBS!$B$80) | I11: =$C11*(Parâmetros!$B$15*(YEAR(WBS!$C$80)=2027)*(MONTH(WBS!$C$80)=6)+(1-Parâmetros!$B$15)*MAX(0,MIN(WBS!$D$80,EDATE(DATE(2027,6,1),1))-MAX(WBS!$C$80,DATE(2027,6,1)))/WBS!$B$80) | J11: =$C11*(Parâmetros!$B$15*(YEAR(WBS!$C$80)=2027)*(MONTH(WBS!$C$80)=7)+(1-Parâmetros!$B$15)*MAX(0,MIN(WBS!$D$80,EDATE(DATE(2027,7,1),1))-MAX(WBS!$C$80,DATE(2027,7,1)))/WBS!$B$80) | K11: =$C11*(Parâmetros!$B$15*(YEAR(WBS!$C$80)=2027)*(MONTH(WBS!$C$80)=8)+(1-Parâmetros!$B$15)*MAX(0,MIN(WBS!$D$80,EDATE(DATE(2027,8,1),1))-MAX(WBS!$C$80,DATE(2027,8,1)))/WBS!$B$80) | L11: =$C11*(Parâmetros!$B$15*(YEAR(WBS!$C$80)=2027)*(MONTH(WBS!$C$80)=9)+(1-Parâmetros!$B$15)*MAX(0,MIN(WBS!$D$80,EDATE(DATE(2027,9,1),1))-MAX(WBS!$C$80,DATE(2027,9,1)))/WBS!$B$80) | M11: =$C11*(Parâmetros!$B$15*(YEAR(WBS!$C$80)=2027)*(MONTH(WBS!$C$80)=10)+(1-Parâmetros!$B$15)*MAX(0,MIN(WBS!$D$80,EDATE(DATE(2027,10,1),1))-MAX(WBS!$C$80,DATE(2027,10,1)))/WBS!$B$80) | N11: =$C11*(Parâmetros!$B$15*(YEAR(WBS!$C$80)=2027)*(MONTH(WBS!$C$80)=11)+(1-Parâmetros!$B$15)*MAX(0,MIN(WBS!$D$80,EDATE(DATE(2027,11,1),1))-MAX(WBS!$C$80,DATE(2027,11,1)))/WBS!$B$80) | O11: =$C11*(Parâmetros!$B$15*(YEAR(WBS!$C$80)=2027)*(MONTH(WBS!$C$80)=12)+(1-Parâmetros!$B$15)*MAX(0,MIN(WBS!$D$80,EDATE(DATE(2027,12,1),1))-MAX(WBS!$C$80,DATE(2027,12,1)))/WBS!$B$80) | P11: =SUM(D11:O11) | Q11: =IF(ABS(P11-C11)<0.5,"ok","DIVERGE")
A12: 92102 | B12: =Carteira!C11 | C12: =Carteira!L11 | D12: =$C12*(Parâmetros!$B$15*(YEAR(WBS!$C$91)=2027)*(MONTH(WBS!$C$91)=1)+(1-Parâmetros!$B$15)*MAX(0,MIN(WBS!$D$91,EDATE(DATE(2027,1,1),1))-MAX(WBS!$C$91,DATE(2027,1,1)))/WBS!$B$91) | E12: =$C12*(Parâmetros!$B$15*(YEAR(WBS!$C$91)=2027)*(MONTH(WBS!$C$91)=2)+(1-Parâmetros!$B$15)*MAX(0,MIN(WBS!$D$91,EDATE(DATE(2027,2,1),1))-MAX(WBS!$C$91,DATE(2027,2,1)))/WBS!$B$91) | F12: =$C12*(Parâmetros!$B$15*(YEAR(WBS!$C$91)=2027)*(MONTH(WBS!$C$91)=3)+(1-Parâmetros!$B$15)*MAX(0,MIN(WBS!$D$91,EDATE(DATE(2027,3,1),1))-MAX(WBS!$C$91,DATE(2027,3,1)))/WBS!$B$91) | G12: =$C12*(Parâmetros!$B$15*(YEAR(WBS!$C$91)=2027)*(MONTH(WBS!$C$91)=4)+(1-Parâmetros!$B$15)*MAX(0,MIN(WBS!$D$91,EDATE(DATE(2027,4,1),1))-MAX(WBS!$C$91,DATE(2027,4,1)))/WBS!$B$91) | H12: =$C12*(Parâmetros!$B$15*(YEAR(WBS!$C$91)=2027)*(MONTH(WBS!$C$91)=5)+(1-Parâmetros!$B$15)*MAX(0,MIN(WBS!$D$91,EDATE(DATE(2027,5,1),1))-MAX(WBS!$C$91,DATE(2027,5,1)))/WBS!$B$91) | I12: =$C12*(Parâmetros!$B$15*(YEAR(WBS!$C$91)=2027)*(MONTH(WBS!$C$91)=6)+(1-Parâmetros!$B$15)*MAX(0,MIN(WBS!$D$91,EDATE(DATE(2027,6,1),1))-MAX(WBS!$C$91,DATE(2027,6,1)))/WBS!$B$91) | J12: =$C12*(Parâmetros!$B$15*(YEAR(WBS!$C$91)=2027)*(MONTH(WBS!$C$91)=7)+(1-Parâmetros!$B$15)*MAX(0,MIN(WBS!$D$91,EDATE(DATE(2027,7,1),1))-MAX(WBS!$C$91,DATE(2027,7,1)))/WBS!$B$91) | K12: =$C12*(Parâmetros!$B$15*(YEAR(WBS!$C$91)=2027)*(MONTH(WBS!$C$91)=8)+(1-Parâmetros!$B$15)*MAX(0,MIN(WBS!$D$91,EDATE(DATE(2027,8,1),1))-MAX(WBS!$C$91,DATE(2027,8,1)))/WBS!$B$91) | L12: =$C12*(Parâmetros!$B$15*(YEAR(WBS!$C$91)=2027)*(MONTH(WBS!$C$91)=9)+(1-Parâmetros!$B$15)*MAX(0,MIN(WBS!$D$91,EDATE(DATE(2027,9,1),1))-MAX(WBS!$C$91,DATE(2027,9,1)))/WBS!$B$91) | M12: =$C12*(Parâmetros!$B$15*(YEAR(WBS!$C$91)=2027)*(MONTH(WBS!$C$91)=10)+(1-Parâmetros!$B$15)*MAX(0,MIN(WBS!$D$91,EDATE(DATE(2027,10,1),1))-MAX(WBS!$C$91,DATE(2027,10,1)))/WBS!$B$91) | N12: =$C12*(Parâmetros!$B$15*(YEAR(WBS!$C$91)=2027)*(MONTH(WBS!$C$91)=11)+(1-Parâmetros!$B$15)*MAX(0,MIN(WBS!$D$91,EDATE(DATE(2027,11,1),1))-MAX(WBS!$C$91,DATE(2027,11,1)))/WBS!$B$91) | O12: =$C12*(Parâmetros!$B$15*(YEAR(WBS!$C$91)=2027)*(MONTH(WBS!$C$91)=12)+(1-Parâmetros!$B$15)*MAX(0,MIN(WBS!$D$91,EDATE(DATE(2027,12,1),1))-MAX(WBS!$C$91,DATE(2027,12,1)))/WBS!$B$91) | P12: =SUM(D12:O12) | Q12: =IF(ABS(P12-C12)<0.5,"ok","DIVERGE")
A13: 70838 | B13: =Carteira!C12 | C13: =Carteira!L12 | D13: =$C13*(Parâmetros!$B$15*(YEAR(WBS!$C$102)=2027)*(MONTH(WBS!$C$102)=1)+(1-Parâmetros!$B$15)*MAX(0,MIN(WBS!$D$102,EDATE(DATE(2027,1,1),1))-MAX(WBS!$C$102,DATE(2027,1,1)))/WBS!$B$102) | E13: =$C13*(Parâmetros!$B$15*(YEAR(WBS!$C$102)=2027)*(MONTH(WBS!$C$102)=2)+(1-Parâmetros!$B$15)*MAX(0,MIN(WBS!$D$102,EDATE(DATE(2027,2,1),1))-MAX(WBS!$C$102,DATE(2027,2,1)))/WBS!$B$102) | F13: =$C13*(Parâmetros!$B$15*(YEAR(WBS!$C$102)=2027)*(MONTH(WBS!$C$102)=3)+(1-Parâmetros!$B$15)*MAX(0,MIN(WBS!$D$102,EDATE(DATE(2027,3,1),1))-MAX(WBS!$C$102,DATE(2027,3,1)))/WBS!$B$102) | G13: =$C13*(Parâmetros!$B$15*(YEAR(WBS!$C$102)=2027)*(MONTH(WBS!$C$102)=4)+(1-Parâmetros!$B$15)*MAX(0,MIN(WBS!$D$102,EDATE(DATE(2027,4,1),1))-MAX(WBS!$C$102,DATE(2027,4,1)))/WBS!$B$102) | H13: =$C13*(Parâmetros!$B$15*(YEAR(WBS!$C$102)=2027)*(MONTH(WBS!$C$102)=5)+(1-Parâmetros!$B$15)*MAX(0,MIN(WBS!$D$102,EDATE(DATE(2027,5,1),1))-MAX(WBS!$C$102,DATE(2027,5,1)))/WBS!$B$102) | I13: =$C13*(Parâmetros!$B$15*(YEAR(WBS!$C$102)=2027)*(MONTH(WBS!$C$102)=6)+(1-Parâmetros!$B$15)*MAX(0,MIN(WBS!$D$102,EDATE(DATE(2027,6,1),1))-MAX(WBS!$C$102,DATE(2027,6,1)))/WBS!$B$102) | J13: =$C13*(Parâmetros!$B$15*(YEAR(WBS!$C$102)=2027)*(MONTH(WBS!$C$102)=7)+(1-Parâmetros!$B$15)*MAX(0,MIN(WBS!$D$102,EDATE(DATE(2027,7,1),1))-MAX(WBS!$C$102,DATE(2027,7,1)))/WBS!$B$102) | K13: =$C13*(Parâmetros!$B$15*(YEAR(WBS!$C$102)=2027)*(MONTH(WBS!$C$102)=8)+(1-Parâmetros!$B$15)*MAX(0,MIN(WBS!$D$102,EDATE(DATE(2027,8,1),1))-MAX(WBS!$C$102,DATE(2027,8,1)))/WBS!$B$102) | L13: =$C13*(Parâmetros!$B$15*(YEAR(WBS!$C$102)=2027)*(MONTH(WBS!$C$102)=9)+(1-Parâmetros!$B$15)*MAX(0,MIN(WBS!$D$102,EDATE(DATE(2027,9,1),1))-MAX(WBS!$C$102,DATE(2027,9,1)))/WBS!$B$102) | M13: =$C13*(Parâmetros!$B$15*(YEAR(WBS!$C$102)=2027)*(MONTH(WBS!$C$102)=10)+(1-Parâmetros!$B$15)*MAX(0,MIN(WBS!$D$102,EDATE(DATE(2027,10,1),1))-MAX(WBS!$C$102,DATE(2027,10,1)))/WBS!$B$102) | N13: =$C13*(Parâmetros!$B$15*(YEAR(WBS!$C$102)=2027)*(MONTH(WBS!$C$102)=11)+(1-Parâmetros!$B$15)*MAX(0,MIN(WBS!$D$102,EDATE(DATE(2027,11,1),1))-MAX(WBS!$C$102,DATE(2027,11,1)))/WBS!$B$102) | O13: =$C13*(Parâmetros!$B$15*(YEAR(WBS!$C$102)=2027)*(MONTH(WBS!$C$102)=12)+(1-Parâmetros!$B$15)*MAX(0,MIN(WBS!$D$102,EDATE(DATE(2027,12,1),1))-MAX(WBS!$C$102,DATE(2027,12,1)))/WBS!$B$102) | P13: =SUM(D13:O13) | Q13: =IF(ABS(P13-C13)<0.5,"ok","DIVERGE")
A14: 70978 | B14: =Carteira!C13 | C14: =Carteira!L13 | D14: =$C14*(Parâmetros!$B$15*(YEAR(WBS!$C$113)=2027)*(MONTH(WBS!$C$113)=1)+(1-Parâmetros!$B$15)*MAX(0,MIN(WBS!$D$113,EDATE(DATE(2027,1,1),1))-MAX(WBS!$C$113,DATE(2027,1,1)))/WBS!$B$113) | E14: =$C14*(Parâmetros!$B$15*(YEAR(WBS!$C$113)=2027)*(MONTH(WBS!$C$113)=2)+(1-Parâmetros!$B$15)*MAX(0,MIN(WBS!$D$113,EDATE(DATE(2027,2,1),1))-MAX(WBS!$C$113,DATE(2027,2,1)))/WBS!$B$113) | F14: =$C14*(Parâmetros!$B$15*(YEAR(WBS!$C$113)=2027)*(MONTH(WBS!$C$113)=3)+(1-Parâmetros!$B$15)*MAX(0,MIN(WBS!$D$113,EDATE(DATE(2027,3,1),1))-MAX(WBS!$C$113,DATE(2027,3,1)))/WBS!$B$113) | G14: =$C14*(Parâmetros!$B$15*(YEAR(WBS!$C$113)=2027)*(MONTH(WBS!$C$113)=4)+(1-Parâmetros!$B$15)*MAX(0,MIN(WBS!$D$113,EDATE(DATE(2027,4,1),1))-MAX(WBS!$C$113,DATE(2027,4,1)))/WBS!$B$113) | H14: =$C14*(Parâmetros!$B$15*(YEAR(WBS!$C$113)=2027)*(MONTH(WBS!$C$113)=5)+(1-Parâmetros!$B$15)*MAX(0,MIN(WBS!$D$113,EDATE(DATE(2027,5,1),1))-MAX(WBS!$C$113,DATE(2027,5,1)))/WBS!$B$113) | I14: =$C14*(Parâmetros!$B$15*(YEAR(WBS!$C$113)=2027)*(MONTH(WBS!$C$113)=6)+(1-Parâmetros!$B$15)*MAX(0,MIN(WBS!$D$113,EDATE(DATE(2027,6,1),1))-MAX(WBS!$C$113,DATE(2027,6,1)))/WBS!$B$113) | J14: =$C14*(Parâmetros!$B$15*(YEAR(WBS!$C$113)=2027)*(MONTH(WBS!$C$113)=7)+(1-Parâmetros!$B$15)*MAX(0,MIN(WBS!$D$113,EDATE(DATE(2027,7,1),1))-MAX(WBS!$C$113,DATE(2027,7,1)))/WBS!$B$113) | K14: =$C14*(Parâmetros!$B$15*(YEAR(WBS!$C$113)=2027)*(MONTH(WBS!$C$113)=8)+(1-Parâmetros!$B$15)*MAX(0,MIN(WBS!$D$113,EDATE(DATE(2027,8,1),1))-MAX(WBS!$C$113,DATE(2027,8,1)))/WBS!$B$113) | L14: =$C14*(Parâmetros!$B$15*(YEAR(WBS!$C$113)=2027)*(MONTH(WBS!$C$113)=9)+(1-Parâmetros!$B$15)*MAX(0,MIN(WBS!$D$113,EDATE(DATE(2027,9,1),1))-MAX(WBS!$C$113,DATE(2027,9,1)))/WBS!$B$113) | M14: =$C14*(Parâmetros!$B$15*(YEAR(WBS!$C$113)=2027)*(MONTH(WBS!$C$113)=10)+(1-Parâmetros!$B$15)*MAX(0,MIN(WBS!$D$113,EDATE(DATE(2027,10,1),1))-MAX(WBS!$C$113,DATE(2027,10,1)))/WBS!$B$113) | N14: =$C14*(Parâmetros!$B$15*(YEAR(WBS!$C$113)=2027)*(MONTH(WBS!$C$113)=11)+(1-Parâmetros!$B$15)*MAX(0,MIN(WBS!$D$113,EDATE(DATE(2027,11,1),1))-MAX(WBS!$C$113,DATE(2027,11,1)))/WBS!$B$113) | O14: =$C14*(Parâmetros!$B$15*(YEAR(WBS!$C$113)=2027)*(MONTH(WBS!$C$113)=12)+(1-Parâmetros!$B$15)*MAX(0,MIN(WBS!$D$113,EDATE(DATE(2027,12,1),1))-MAX(WBS!$C$113,DATE(2027,12,1)))/WBS!$B$113) | P14: =SUM(D14:O14) | Q14: =IF(ABS(P14-C14)<0.5,"ok","DIVERGE")
A15: 89249 | B15: =Carteira!C14 | C15: =Carteira!L14 | D15: =$C15*(Parâmetros!$B$15*(YEAR(WBS!$C$124)=2027)*(MONTH(WBS!$C$124)=1)+(1-Parâmetros!$B$15)*MAX(0,MIN(WBS!$D$124,EDATE(DATE(2027,1,1),1))-MAX(WBS!$C$124,DATE(2027,1,1)))/WBS!$B$124) | E15: =$C15*(Parâmetros!$B$15*(YEAR(WBS!$C$124)=2027)*(MONTH(WBS!$C$124)=2)+(1-Parâmetros!$B$15)*MAX(0,MIN(WBS!$D$124,EDATE(DATE(2027,2,1),1))-MAX(WBS!$C$124,DATE(2027,2,1)))/WBS!$B$124) | F15: =$C15*(Parâmetros!$B$15*(YEAR(WBS!$C$124)=2027)*(MONTH(WBS!$C$124)=3)+(1-Parâmetros!$B$15)*MAX(0,MIN(WBS!$D$124,EDATE(DATE(2027,3,1),1))-MAX(WBS!$C$124,DATE(2027,3,1)))/WBS!$B$124) | G15: =$C15*(Parâmetros!$B$15*(YEAR(WBS!$C$124)=2027)*(MONTH(WBS!$C$124)=4)+(1-Parâmetros!$B$15)*MAX(0,MIN(WBS!$D$124,EDATE(DATE(2027,4,1),1))-MAX(WBS!$C$124,DATE(2027,4,1)))/WBS!$B$124) | H15: =$C15*(Parâmetros!$B$15*(YEAR(WBS!$C$124)=2027)*(MONTH(WBS!$C$124)=5)+(1-Parâmetros!$B$15)*MAX(0,MIN(WBS!$D$124,EDATE(DATE(2027,5,1),1))-MAX(WBS!$C$124,DATE(2027,5,1)))/WBS!$B$124) | I15: =$C15*(Parâmetros!$B$15*(YEAR(WBS!$C$124)=2027)*(MONTH(WBS!$C$124)=6)+(1-Parâmetros!$B$15)*MAX(0,MIN(WBS!$D$124,EDATE(DATE(2027,6,1),1))-MAX(WBS!$C$124,DATE(2027,6,1)))/WBS!$B$124) | J15: =$C15*(Parâmetros!$B$15*(YEAR(WBS!$C$124)=2027)*(MONTH(WBS!$C$124)=7)+(1-Parâmetros!$B$15)*MAX(0,MIN(WBS!$D$124,EDATE(DATE(2027,7,1),1))-MAX(WBS!$C$124,DATE(2027,7,1)))/WBS!$B$124) | K15: =$C15*(Parâmetros!$B$15*(YEAR(WBS!$C$124)=2027)*(MONTH(WBS!$C$124)=8)+(1-Parâmetros!$B$15)*MAX(0,MIN(WBS!$D$124,EDATE(DATE(2027,8,1),1))-MAX(WBS!$C$124,DATE(2027,8,1)))/WBS!$B$124) | L15: =$C15*(Parâmetros!$B$15*(YEAR(WBS!$C$124)=2027)*(MONTH(WBS!$C$124)=9)+(1-Parâmetros!$B$15)*MAX(0,MIN(WBS!$D$124,EDATE(DATE(2027,9,1),1))-MAX(WBS!$C$124,DATE(2027,9,1)))/WBS!$B$124) | M15: =$C15*(Parâmetros!$B$15*(YEAR(WBS!$C$124)=2027)*(MONTH(WBS!$C$124)=10)+(1-Parâmetros!$B$15)*MAX(0,MIN(WBS!$D$124,EDATE(DATE(2027,10,1),1))-MAX(WBS!$C$124,DATE(2027,10,1)))/WBS!$B$124) | N15: =$C15*(Parâmetros!$B$15*(YEAR(WBS!$C$124)=2027)*(MONTH(WBS!$C$124)=11)+(1-Parâmetros!$B$15)*MAX(0,MIN(WBS!$D$124,EDATE(DATE(2027,11,1),1))-MAX(WBS!$C$124,DATE(2027,11,1)))/WBS!$B$124) | O15: =$C15*(Parâmetros!$B$15*(YEAR(WBS!$C$124)=2027)*(MONTH(WBS!$C$124)=12)+(1-Parâmetros!$B$15)*MAX(0,MIN(WBS!$D$124,EDATE(DATE(2027,12,1),1))-MAX(WBS!$C$124,DATE(2027,12,1)))/WBS!$B$124) | P15: =SUM(D15:O15) | Q15: =IF(ABS(P15-C15)<0.5,"ok","DIVERGE")
A16: 89307 | B16: =Carteira!C15 | C16: =Carteira!L15 | D16: =$C16*(Parâmetros!$B$15*(YEAR(WBS!$C$135)=2027)*(MONTH(WBS!$C$135)=1)+(1-Parâmetros!$B$15)*MAX(0,MIN(WBS!$D$135,EDATE(DATE(2027,1,1),1))-MAX(WBS!$C$135,DATE(2027,1,1)))/WBS!$B$135) | E16: =$C16*(Parâmetros!$B$15*(YEAR(WBS!$C$135)=2027)*(MONTH(WBS!$C$135)=2)+(1-Parâmetros!$B$15)*MAX(0,MIN(WBS!$D$135,EDATE(DATE(2027,2,1),1))-MAX(WBS!$C$135,DATE(2027,2,1)))/WBS!$B$135) | F16: =$C16*(Parâmetros!$B$15*(YEAR(WBS!$C$135)=2027)*(MONTH(WBS!$C$135)=3)+(1-Parâmetros!$B$15)*MAX(0,MIN(WBS!$D$135,EDATE(DATE(2027,3,1),1))-MAX(WBS!$C$135,DATE(2027,3,1)))/WBS!$B$135) | G16: =$C16*(Parâmetros!$B$15*(YEAR(WBS!$C$135)=2027)*(MONTH(WBS!$C$135)=4)+(1-Parâmetros!$B$15)*MAX(0,MIN(WBS!$D$135,EDATE(DATE(2027,4,1),1))-MAX(WBS!$C$135,DATE(2027,4,1)))/WBS!$B$135) | H16: =$C16*(Parâmetros!$B$15*(YEAR(WBS!$C$135)=2027)*(MONTH(WBS!$C$135)=5)+(1-Parâmetros!$B$15)*MAX(0,MIN(WBS!$D$135,EDATE(DATE(2027,5,1),1))-MAX(WBS!$C$135,DATE(2027,5,1)))/WBS!$B$135) | I16: =$C16*(Parâmetros!$B$15*(YEAR(WBS!$C$135)=2027)*(MONTH(WBS!$C$135)=6)+(1-Parâmetros!$B$15)*MAX(0,MIN(WBS!$D$135,EDATE(DATE(2027,6,1),1))-MAX(WBS!$C$135,DATE(2027,6,1)))/WBS!$B$135) | J16: =$C16*(Parâmetros!$B$15*(YEAR(WBS!$C$135)=2027)*(MONTH(WBS!$C$135)=7)+(1-Parâmetros!$B$15)*MAX(0,MIN(WBS!$D$135,EDATE(DATE(2027,7,1),1))-MAX(WBS!$C$135,DATE(2027,7,1)))/WBS!$B$135) | K16: =$C16*(Parâmetros!$B$15*(YEAR(WBS!$C$135)=2027)*(MONTH(WBS!$C$135)=8)+(1-Parâmetros!$B$15)*MAX(0,MIN(WBS!$D$135,EDATE(DATE(2027,8,1),1))-MAX(WBS!$C$135,DATE(2027,8,1)))/WBS!$B$135) | L16: =$C16*(Parâmetros!$B$15*(YEAR(WBS!$C$135)=2027)*(MONTH(WBS!$C$135)=9)+(1-Parâmetros!$B$15)*MAX(0,MIN(WBS!$D$135,EDATE(DATE(2027,9,1),1))-MAX(WBS!$C$135,DATE(2027,9,1)))/WBS!$B$135) | M16: =$C16*(Parâmetros!$B$15*(YEAR(WBS!$C$135)=2027)*(MONTH(WBS!$C$135)=10)+(1-Parâmetros!$B$15)*MAX(0,MIN(WBS!$D$135,EDATE(DATE(2027,10,1),1))-MAX(WBS!$C$135,DATE(2027,10,1)))/WBS!$B$135) | N16: =$C16*(Parâmetros!$B$15*(YEAR(WBS!$C$135)=2027)*(MONTH(WBS!$C$135)=11)+(1-Parâmetros!$B$15)*MAX(0,MIN(WBS!$D$135,EDATE(DATE(2027,11,1),1))-MAX(WBS!$C$135,DATE(2027,11,1)))/WBS!$B$135) | O16: =$C16*(Parâmetros!$B$15*(YEAR(WBS!$C$135)=2027)*(MONTH(WBS!$C$135)=12)+(1-Parâmetros!$B$15)*MAX(0,MIN(WBS!$D$135,EDATE(DATE(2027,12,1),1))-MAX(WBS!$C$135,DATE(2027,12,1)))/WBS!$B$135) | P16: =SUM(D16:O16) | Q16: =IF(ABS(P16-C16)<0.5,"ok","DIVERGE")
B17: Total mensal – curva WBS | C17: =SUM(C5:C16) | D17: =SUM(D5:D16) | E17: =SUM(E5:E16) | F17: =SUM(F5:F16) | G17: =SUM(G5:G16) | H17: =SUM(H5:H16) | I17: =SUM(I5:I16) | J17: =SUM(J5:J16) | ... P17: =SUM(P5:P16)
B18: Acumulado – curva WBS | D18: =SUM($D17:D17) | E18: =SUM($D17:E17) | F18: =SUM($D17:F17) | G18: =SUM($D17:G17) | H18: =SUM($D17:H17) | I18: =SUM($D17:I17) | J18: =SUM($D17:J17) | K18: =SUM($D17:K17) | ... O18: =SUM($D17:O17)
A20: Referência: cadastro CAPEX "Mensalização 08.10" (rateio linear)
A21: SIGCO | B21: Projeto | C21: Total | D21: Jan | E21: Fev | F21: Mar | G21: Abr | H21: Mai | I21: Jun | J21: Jul | K21: Ago | L21: Set | M21: Out | N21: Nov | O21: Dez | P21: Total
A22: 90811 | B22: =Carteira!C4 | C22: =SUM(D22:O22) | D22: 143320.11 | E22: 143320.11 | F22: 143320.11 | G22: 143320.11 | H22: 163760.56 | I22: 163760.56 | J22: 163760.56 | K22: 163760.37 | L22: 143320.11 | M22: 143320.11 | N22: 143320.11 | O22: 143322 | P22: =SUM(D22:O22)
A23: 91979 | B23: =Carteira!C5 | C23: =SUM(D23:O23) | D23: 19964.907 | E23: 19964.907 | F23: 19964.907 | G23: 19964.907 | H23: 19964.907 | I23: 19964.907 | J23: 19964.907 | K23: 19964.907 | L23: 19964.907 | M23: 19964.907 | N23: 19964.907 | O23: 19967.793 | P23: =SUM(D23:O23)
A24: 92118 | B24: =Carteira!C6 | C24: =SUM(D24:O24) | D24: 9227.8374 | E24: 9227.8374 | F24: 9227.8374 | G24: 9227.8374 | H24: 9227.8374 | I24: 9227.8374 | J24: 9227.8374 | K24: 9227.8374 | L24: 9227.8374 | M24: 9227.8374 | N24: 9227.8374 | O24: 9230.0486 | P24: =SUM(D24:O24)
A25: 89267 | B25: =Carteira!C7 | C25: =SUM(D25:O25) | D25: 66860.108 | E25: 66860.108 | F25: 66860.108 | G25: 66860.108 | H25: 66860.108 | I25: 66860.108 | J25: 66860.108 | K25: 66860.108 | L25: 66860.108 | M25: 66860.108 | N25: 66860.108 | O25: 66861.148 | P25: =SUM(D25:O25)
A26: 92094 | B26: =Carteira!C8 | C26: =SUM(D26:O26) | D26: 32562.34 | E26: 32562.34 | F26: 32562.34 | G26: 32562.34 | H26: 32562.34 | I26: 32562.34 | J26: 32562.34 | K26: 32562.34 | L26: 32562.34 | M26: 32562.34 | N26: 32562.34 | O26: 32564.293 | P26: =SUM(D26:O26)
A27: 92095 | B27: =Carteira!C9 | C27: =SUM(D27:O27) | D27: 10853.964 | E27: 10853.964 | F27: 10853.964 | G27: 10853.964 | H27: 10853.964 | I27: 10853.964 | J27: 10853.964 | K27: 10853.964 | L27: 10853.964 | M27: 10853.964 | N27: 10853.964 | O27: 10856.404 | P27: =SUM(D27:O27)
A28: 92101 | B28: =Carteira!C10 | C28: =SUM(D28:O28) | D28: 9227.8374 | E28: 9227.8374 | F28: 9227.8374 | G28: 9227.8374 | H28: 9227.8374 | I28: 9227.8374 | J28: 9227.8374 | K28: 9227.8374 | L28: 9227.8374 | M28: 9227.8374 | N28: 9227.8374 | O28: 9230.0486 | P28: =SUM(D28:O28)
A29: 92102 | B29: =Carteira!C11 | C29: =SUM(D29:O29) | D29: 9227.8374 | E29: 9227.8374 | F29: 9227.8374 | G29: 9227.8374 | H29: 9227.8374 | I29: 9227.8374 | J29: 9227.8374 | K29: 9227.8374 | L29: 9227.8374 | M29: 9227.8374 | N29: 9227.8374 | O29: 9230.0486 | P29: =SUM(D29:O29)
A30: 70838 | B30: =Carteira!C12 | C30: =SUM(D30:O30) | D30: 33301.104 | E30: 33301.104 | F30: 33301.104 | G30: 33301.104 | H30: 33301.104 | I30: 33301.104 | J30: 33301.104 | K30: 33301.104 | L30: 33301.104 | M30: 33301.104 | N30: 33301.104 | O30: 33302.245 | P30: =SUM(D30:O30)
A31: 70978 | B31: =Carteira!C13 | C31: =SUM(D31:O31) | D31: 33326.044 | E31: 33326.044 | F31: 33326.044 | G31: 33326.044 | H31: 33326.044 | I31: 33326.044 | J31: 33326.044 | K31: 33326.044 | L31: 33326.044 | M31: 33326.044 | N31: 33326.044 | O31: 33327.281 | P31: =SUM(D31:O31)
A32: 89249 | B32: =Carteira!C14 | C32: =SUM(D32:O32) | D32: 33301.104 | E32: 33301.104 | F32: 33301.104 | G32: 33301.104 | H32: 33301.104 | I32: 33301.104 | J32: 33301.104 | K32: 33301.104 | L32: 33301.104 | M32: 33301.104 | N32: 33301.104 | O32: 33302.245 | P32: =SUM(D32:O32)
A33: 89307 | B33: =Carteira!C15 | C33: =SUM(D33:O33) | D33: 27582.142 | E33: 27582.142 | F33: 27582.142 | G33: 27582.142 | H33: 27582.142 | I33: 27582.142 | J33: 27582.142 | K33: 27582.142 | L33: 27582.142 | M33: 27582.142 | N33: 27582.142 | O33: 27585.473 | P33: =SUM(D33:O33)
B34: Total mensal – cadastro 08.10 | C34: =SUM(C22:C33) | D34: =SUM(D22:D33) | E34: =SUM(E22:E33) | F34: =SUM(F22:F33) | G34: =SUM(G22:G33) | H34: =SUM(H22:H33) | I34: =SUM(I22:I33) | J34: =SUM(J22:J33) | ... P34: =SUM(P22:P33)
B35: Diferença (curva WBS − cadastro) | D35: =D17-D34 | E35: =E17-E34 | F35: =F17-F34 | G35: =G17-G34 | H35: =H17-H34 | I35: =I17-I34 | J35: =J17-J34 | K35: =K17-K34 | ... O35: =O17-O34

Sheet Aquisições
A1: Equipamentos e serviços a adquirir/contratar – data necessária em campo
A3: SIGCO | B3: Item | C3: Tensão | D3: Quantidade | E3: Data necessária (início da execução) | F3: Nº PMA/RFP | G3: Status
A4: 90811 | B4: Regulador de tensão | C4: 34,5 kV | D4: 3 | E4: =WBS!C14 | G4: A confirmar
A5: 90811 | B5: Religador automático | C5: 34,5 kV | D5: 4 | E5: =WBS!C14 | G5: A confirmar
A6: 90811 | B6: Chave faca (1 N.F + 1 N.A) + poste e 0,25 km de RD MT cabo 3#1/0 AWG | C6: 34,5 kV | D6: 1 | E6: =WBS!C14 | G6: A confirmar
A7: 91979 | B7: Religador rural | C7: 34,5 kV | D7: 1 | E7: =WBS!C25 | G7: A confirmar
A8: 91979 | B8: TripSaver (religador monofásico) | C8: — | D8: 3 | E8: =WBS!C25 | G8: A confirmar
A9: 92118 | B9: Religador automático | C9: 13,8 kV | D9: 1 | E9: =WBS!C36 | G9: A confirmar
A10: 89267 | B10: Regulador de tensão | C10: 34,5 kV | D10: 2 | E10: =WBS!C47 | G10: A confirmar
A11: 92094 | B11: Religador automático | C11: 34,5 kV | D11: 3 | E11: =WBS!C58 | G11: A confirmar
A12: 92095 | B12: Religador automático | C12: 34,5 kV | D12: 1 | E12: =WBS!C69 | G12: A confirmar
A13: 92101 | B13: Religador automático (N.A) | C13: 13,8 kV | D13: 1 | E13: =WBS!C80 | G13: A confirmar
A14: 92102 | B14: Religador automático (N.F) | C14: 13,8 kV | D14: 1 | E14: =WBS!C91 | G14: A confirmar
A15: 70838 | B15: Regulador de tensão | C15: 34,5 kV | D15: 1 | E15: =WBS!C102 | G15: A confirmar
A16: 70978 | B16: Regulador de tensão | C16: 34,5 kV | D16: 1 | E16: =WBS!C113 | G16: A confirmar
A17: 89249 | B17: Regulador de tensão | C17: 34,5 kV | D17: 1 | E17: =WBS!C124 | G17: A confirmar
A18: 89307 | B18: Regulador de tensão | C18: 13,8 kV | D18: 1 | E18: =WBS!C135 | G18: A confirmar
A19: 89307 | B19: Religador 13,8 kV – remanejamento (equipamento existente) | C19: 13,8 kV | D19: 1 | E19: =WBS!C135 | G19: A confirmar
A21: Resumo: 9 RT (8 de 34,5 kV e 1 de 13,8 kV); 12 RL novos (9 de 34,5 kV e 3 de 13,8 kV) + 1 RL remanejado; 3 TripSavers.
A22: Atenção: o prazo de fornecimento não foi usado no cronograma. A ATA do TM (06/10/2026) cita lead time de 210 dias da SEL para IEDs/relés – validar com Suprimentos antes do PRM.
A23: Contratação da EPS: O.S. assinada antes da 1ª execução (premissa do template KOM).

Sheet Base PN 2026 (RL-RT)
A1: Evidência dos prazos – blocos de instalação de RL e RT do WBS PN 2026 (arquivo WBS.xlsx)
A3: Linha WBS.xlsx | B3: Bloco (PN 2026) | C3: Equip. | D3: Executar Obras (dias) | E3: Duração total (dias) | F3: Início | G3: Término | H3: Usado como referência?
A4: 54 | B4: BLOCO 1 – Bay e SDMT AL 10 SE Palmas III – Instalação de 5 RL e remanejamento de 1 RL 13,8 kV (71018) | C4: 6 | D4: 45 | E4: 101 | F4: 46244 | G4: 46345 | H4: Sim – pacote 5+ equipamentos (P45)
A5: 105 | B5: BLOCO 3 – LDMT AL 2 de Araguaína I – Instalação de 5 RL 13,8 kV (73521) – Parte III | C5: 5 | D5: 45 | E5: 101 | F5: 46195 | G5: 46296 | H5: Sim – pacote 5+ equipamentos (P45)
A6: 146 | B6: LD Bielândia – Palmeirante – Instalação de um regulador de tensão 34,5 kV (72240) | C6: 1 | D6: 30 | E6: 86 | F6: 46210 | G6: 46296 | H6: Sim – pacote até 4 (P30)
A7: 157 | B7: LD Araguaína – Araguanã – Instalação de um regulador de tensão 34,5 kV (71579) | C7: 1 | D7: 30 | E7: 86 | F7: 46210 | G7: 46296 | H7: Sim – pacote até 4 (P30)
A8: 188 | B8: AL SE Bielândia – Realocar RL (1), Instalar Religador 34,5 kV (2), Instalar Regulador de Tensão 34,5 kV (1) (71139) – Parte III | C8: 4 | D8: 30 | E8: 87 | F8: 46202 | G8: 46289 | H8: Sim – pacote até 4 (P30)
A9: 219 | B9: LD Paranã – Palmeirópolis – Remanejamento de Regulador de Tensão 34,5 kV (72938) | C9: 1 | D9: 30 | E9: 87 | F9: 46153 | G9: 46240 | H9: Sim – pacote até 4 (P30)
A10: 240 | B10: SDMT AL 01 de Palmeirópolis – Remanejar 1 Religador 13,8 kV (81319) – Parte II | C10: 1 | D10: 30 | E10: 87 | F10: 46216 | G10: 46303 | H10: Sim – pacote até 4 (P30)
A11: 65 | B11: BLOCO 2 – Instalação de 4 Banco Capacitor 300 kVAr (71018) | C11: 4 | D11: 30 | E11: 87 | F11: 46244 | G11: 46331 | H11: Não – banco de capacitores (fora do escopo RL/RT)
A12: 126 | B12: LDMT 1 e 6 de Araguaína III – Instalação de 6 bancos de capacitores (81179) – Parte II | C12: 6 | D12: 30 | E12: 87 | F12: 46188 | G12: 46275 | H12: Não – banco de capacitores (fora do escopo RL/RT)
A14: Não utilizados: Planejamento (PMA, projeto executivo, site survey), obras de construção/recapacitação de rede (120–150 dias de execução) e bancos de capacitores.
A15: Etapas comuns a todos os blocos RL/RT: Fiscalização 12 | Cadastro EO 10 | TCI/Integração final 15 | GAT 8 | Comissionar 15 | Enc. Técnico 7 (úteis) | Enc. Contábil 3 (úteis).

Sheet Carteira
A1: Carteira PN 2027 – 12 SIGCOs de instalação de RL e RT (GP: Sandro Padilha Dias Junior – DCMD)
A3: SIGCO | B3: Capítulo PN | C3: Projeto | D3: Escopo (equipamentos) | E3: RL | F3: RT | G3: TripSaver | H3: Nº equip. | I3: Pacote de prazo | J3: Meta de energização | K3: Orçamento Agosto (R$) | L3: Orçamento 08.10 (R$) – aprovado | M3: Δ 08.10 − Agosto (R$) | N3: Benefício esperado
A4: 90811 | B4: Qualidade do Produto | C4: Instalação de RL e RT - LD UHE Isamu - Ponte Alta - 1UI1 - QP | D4: 4 RL 34,5 kV + 3 RT 34,5 kV (+ 0,25 km RD MT e 2 chaves faca) | E4: 4 | F4: 3 | G4: 0 | H4: 7 | I4: P45 | J4: 46507 | K4: 1627897 | L4: 1801604.8 | M4: =L4-K4 | N4: Tensão 0,91 → 0,95 pu
A5: 91979 | B5: Qualidade do Serviço | C5: Estudo de QS - LD Gurupi - Duere | D5: 1 RL rural 34,5 kV + 3 TripSaver | E5: 1 | F5: 0 | G5: 3 | H5: 4 | I5: P30 | J5: 46538 | K5: 275195.36 | L5: 239581.77 | M5: =L5-K5 | N5: DEC −0,557 h / FEC −0,104 (base conjunto)
A6: 92118 | B6: Qualidade do Serviço | C6: Estudo de QS - 4 de Araguaína IV | D6: 1 RL automático 13,8 kV | E6: 1 | F6: 0 | G6: 0 | H6: 1 | I6: P30 | J6: 46538 | K6: 121831.52 | L6: 110736.26 | M6: =L6-K6 | N6: DEC −0,078 h / FEC −0,030 (base conjunto)
A7: 89267 | B7: Qualidade do Produto | C7: Instalação de RT - LD Xambioá II - Araguanã - 2XB2 - QP | D7: 2 RT 34,5 kV | E7: 0 | F7: 2 | G7: 0 | H7: 2 | I7: P30 | J7: 46538 | K7: 1083084.6 | L7: 802322.33 | M7: =L7-K7 | N7: Tensão 0,929 → 0,945 pu
A8: 92094 | B8: Qualidade do Serviço | C8: Estudo de QS - LD Palmas - Aparecida do Rio Negro | D8: 3 RL automáticos 34,5 kV | E8: 3 | F8: 0 | G8: 0 | H8: 3 | I8: P30 | J8: 46568 | K8: 505316.58 | L8: 390750.03 | M8: =L8-K8 | N8: DEC −0,402 h / FEC −0,204 (base conjunto)
A9: 92095 | B9: Qualidade do Serviço | C9: Estudo de QS - LD Palmas - Lajeado | D9: 1 RL automático 34,5 kV | E9: 1 | F9: 0 | G9: 0 | H9: 1 | I9: P30 | J9: 46568 | K9: 168438.86 | L9: 130250.01 | M9: =L9-K9 | N9: DEC −0,325 h / FEC −0,069 (base conjunto)
A10: 92101 | B10: Qualidade do Serviço | C10: Estudo de QS - 8 de Palmas IV | D10: 1 RL automático 13,8 kV (N.A) | E10: 1 | F10: 0 | G10: 0 | H10: 1 | I10: P30 | J10: 46568 | K10: 121831.52 | L10: 110736.26 | M10: =L10-K10 | N10: DEC −0,141 h / FEC −0,076 (base conjunto)
A11: 92102 | B11: Qualidade do Serviço | C11: Estudo de QS - 6 de Palmas IV | D11: 1 RL automático 13,8 kV (N.F) | E11: 1 | F11: 0 | G11: 0 | H11: 1 | I11: P30 | J11: 46568 | K11: 121831.52 | L11: 110736.26 | M11: =L11-K11 | N11: DEC −0,043 h / FEC −0,017 (base conjunto)
A12: 70838 | B12: Qualidade do Produto | C12: Instalação de RT - LD Cristalândia - Lagoa da Confusão | D12: 1 RT 34,5 kV | E12: 0 | F12: 1 | G12: 0 | H12: 1 | I12: P30 | J12: 46568 | K12: 539995.52 | L12: 399614.39 | M12: =L12-K12 | N12: Tensão 0,91 → 0,96 pu
A13: 70978 | B13: Qualidade do Produto | C13: Instalação de RT e Balanceamento de Fase - LD Paraíso I - Caseara - 2PR0 - QP | D13: 1 RT 34,5 kV + balanceamento de fase (3 ramais) | E13: 0 | F13: 1 | G13: 0 | H13: 1 | I13: P30 | J13: 46568 | K13: 540294.9 | L13: 399913.77 | M13: =L13-K13 | N13: Tensão 0,91 → 0,97 pu
A14: 89249 | B14: Qualidade do Produto | C14: Instalação de RT - LD Araguaína - Babaçulândia - 2AR0 - QP | D14: 1 RT 34,5 kV | E14: 0 | F14: 1 | G14: 0 | H14: 1 | I14: P30 | J14: 46630 | K14: 539995.52 | L14: 399614.39 | M14: =L14-K14 | N14: Tensão 0,921 → 0,953 pu
A15: 89307 | B15: Qualidade do Produto | C15: Instalação de RT - 1 de Figueirópolis - 2FGR - QP | D15: 1 RT 13,8 kV + remanejamento de 1 RL 13,8 kV | E15: 1 | F15: 1 | G15: 0 | H15: 2 | I15: P30 | J15: 46630 | K15: 373175.86 | L15: 330989.03 | M15: =L15-K15 | N15: Tensão 0,92 → 0,96 pu
C16: Total da carteira | E16: =SUM(E4:E15) | F16: =SUM(F4:F15) | G16: =SUM(G4:G15) | H16: =SUM(H4:H15) | K16: =SUM(K4:K15) | L16: =SUM(L4:L15) | M16: =SUM(M4:M15)
A18: Fontes: Planejamento PN.xlsx (aba CAPEX), Cadastro_CAPEX_2027_2029 (Orçamento 08.10), fichas dos projetos 2027 (PDF), TM-Transfer Meeting 06/10/2026 (meta de energização).
A19: RL = religador (inclui 1 RL rural 34,5 kV no SIGCO 91979 e 1 RL remanejado no 89307); RT = regulador de tensão; pacote P30 = até 4 equipamentos, P45 = 5 ou mais.

Sheet Parâmetros
A1: Parâmetros do cronograma – PN 2027 (instalação de RL e RT)
A2: Prazos extraídos SOMENTE dos blocos de instalação de religadores (RL) e reguladores de tensão (RT) do WBS PN 2026. Células em azul são entradas editáveis; todo o cronograma recalcula a partir delas.
A4: Etapa (nome igual ao WBS 2026) | B4: Dias | C4: Tipo de dia | D4: Regra de encadeamento | E4: Origem do prazo (WBS PN 2026)
A5: Executar Obras – pacote até 4 equipamentos (P30) | B5: 30 | C5: corrido | D5: Início = dado de entrada (calculado de trás para frente a partir da meta de energização) | E5: Blocos RT 72240, RT 71579, RT 72938, RL 81319 e AL SE Bielândia 71139 (1 a 4 equipamentos): 30 dias
A6: Executar Obras – pacote com 5 ou mais equipamentos (P45) | B6: 45 | C6: corrido | D6: Idem | E6: BLOCO 1 (5 RL + 1 remanej., SIGCO 71018) e BLOCO 3 (5 RL, SIGCO 73521): 45 dias
A7: Fiscalização | B7: 12 | C7: corrido | D7: Inicia no 1º dia útil após Obras Concluídas | E7: Todos os blocos RL/RT: 12 dias
A8: Cadastro EO/ Integração parcial | B8: 10 | C8: corrido | D8: Inicia no 1º dia útil após a Fiscalização | E8: Todos os blocos RL/RT: 10 dias
A9: Entrega do TCI pela empreiteira / Integração final | B9: 15 | C9: corrido | D9: Inicia no 1º dia útil após o Cadastro EO | E9: Todos os blocos RL/RT: 15 dias
A10: Abertura de chamado/ Atendimento GAT | B10: 8 | C10: corrido | D10: Paralela: inicia junto com a Entrega do TCI | E10: Todos os blocos RL/RT: 8 dias
A11: Comissionar Equipamentos | B11: 15 | C11: corrido | D11: Paralela: inicia junto com a Entrega do TCI; término = Equipamentos em Operação | E11: Todos os blocos RL/RT: 15 dias
A12: Encerramento Técnico | B12: 7 | C12: útil | D12: Inicia no 1º dia útil após Equipamentos em Operação | E12: Todos os blocos RL/RT: 7 dias úteis
A13: Encerramento Contábil | B13: 3 | C13: útil | D13: Inicia no 1º dia útil após o Encerramento Técnico | E13: Todos os blocos RL/RT: 3 dias úteis
A15: Parcela de material na curva orçamentária | B15: 0.6 | D15: Referência: KOM 2026 (material R$ 15,48 mi de R$ 25,79 mi = 60%). Material reconhecido no mês de início da execução; serviço rateado pelos dias de execução.
A16: Restrição: encerramento contábil até | B16: 46708 | D16: Template KOM PMO-ETO (restrição padrão).
A18: Feriados considerados (dias úteis)
A19: Independência | B19: 46272
A20: N. Sra. Aparecida | B20: 46307
A21: Finados | B21: 46328
A22: Proclamação da República | B22: 46341
A23: Natal | B23: 46381
A24: Confraternização Universal | B24: 46388
A25: Sexta-feira Santa | B25: 46472
A26: Tiradentes | B26: 46498
A27: Dia do Trabalho | B27: 46508
A28: Corpus Christi | B28: 46534
A29: Independência | B29: 46637
A30: N. Sra. Aparecida | B30: 46672
... A33: Natal | B33: 46746
