Workbook

Sheet WBS_Cronograma
A1: Obras de Distribuição 2027 – Instalação de Equipamentos Especiais (RL / RT) | WBS e Cronograma
A2: GP: Sandro Padilha Dias Junior | DCMD | Base: Cadastro CAPEX 2027-2029 (Orçamento 08.10) e TM 06/10/2026 | Dias corridos; término = início + duração. Células em azul são entradas: altere a duração ou a data-alvo de operação e o bloco é reprogramado.
A4: EDT | B4: Nome da tarefa | C4: Regional | D4: SIGCO | E4: Duração (dias) | F4: Início | G4: Término | H4: Responsável | I4: Energização necessária (ASPO) | J4: Folga até fim do mês (dias) | K4: Status
A5: 1 | B5: GERENCIAMENTO DO PROJETO (PMBOK) | E5: =G5-F5 -> 337 | F5: =MIN(F6:F10) -> 46301 | G5: =MAX(G6:G10) -> 46638
A6: 1.1 | B6: Transfer Meeting (TM) | E6: 0 | F6: 46301 | G6: =F6+E6 -> 46301 | H6: ASGP / ASPO | K6: Concluído
A7: 1.2 | B7: Kickoff Meeting (KOM) | E7: 0 | F7: 46324 | G7: =F7+E7 -> 46324 | H7: GP / PMO | K7: A iniciar
A8: 1.3 | B8: Project Review Meeting (PRM) / linha de base | E8: 0 | F8: 46358 | G8: =F8+E8 -> 46358 | H8: GP / PMO | K8: A iniciar
A9: 1.4 | B9: Follow-up Meetings (FUM) mensais | E9: mensal | F9: 46402 | G9: 46615 | H9: GP | K9: A iniciar
A10: 1.5 | B10: Close Meeting (CM) | E10: 0 | F10: =MAX(G33,G44,G55,G67,G78,G89,G100,G111,G122,G133,G144,G155,G167,G178,G189)+7 -> 46638 | G10: =F10+E10 -> 46638 | H10: GP / PMO | K10: A iniciar
A11: 2 | B11: PLANEJAMENTO E SUPRIMENTOS | E11: =G11-F11 -> 212 | F11: =MIN(F12:F21) -> 46329 | G11: =MAX(G12:G21) -> 46541
A12: 2.1 | B12: Criar PMA de materiais específicos (RL, RT, TripSaver) | E12: 30 | F12: 46329 | G12: =F12+E12 -> 46359 | H12: GP / Suprimentos | K12: A iniciar
A13: 2.2 | B13: Realizar estudo Site Survey | E13: 30 | F13: 46335 | G13: =F13+E13 -> 46365 | H13: DCMD / Projetista | K13: A iniciar
A14: 2.3 | B14: Elaborar projetos executivos | E14: 60 | F14: 46329 | G14: =F14+E14 -> 46389 | H14: Projetista | K14: A iniciar
A15: 2.4 | B15: Analisar projetos executivos (COPC) | E15: 15 | F15: 46391 | G15: =F15+E15 -> 46406 | H15: COPC | K15: A iniciar
A16: 2.5 | B16: Check de consistência orçamento x projeto executivo | E16: 10 | F16: 46407 | G16: =F16+E16 -> 46417 | H16: GP | K16: A iniciar
A17: 2.6 | B17: Report da análise para ASPO/DCMD | E17: 5 | F17: 46419 | G17: =F17+E17 -> 46424 | H17: GP | K17: A iniciar
A18: 2.7 | B18: Receber equipamentos - Lote 1 (B1, B2 e B4 a B12) | E18: 0 | F18: 46482 | G18: =F18+E18 -> 46482 | H18: DEOP / Suprimentos | K18: A iniciar
A19: 2.8 | B19: Receber equipamentos - Lote 2 (B3 e B13) | E19: 0 | F19: =MIN(F46,F180)-7 -> 46535 | G19: =F19+E19 -> 46535 | H19: DEOP / Suprimentos | K19: A iniciar
A20: 2.9 | B20: Emitir O.S. e mobilizar EPS - Lote 1 | E20: 5 | F20: =G20-E20 -> 46477 | G20: =MIN(F24,F35,F58,F80,F91,F102,F113,F124,F135,F146,F158)-1 -> 46482 | H20: DCMD / Contratação | K20: A iniciar
A21: 2.10 | B21: Emitir O.S. e mobilizar EPS - Lote 2 | E21: 5 | F21: =G21-E21 -> 46536 | G21: =MIN(F46,F180)-1 -> 46541 | H21: DCMD / Contratação | K21: A iniciar
A22: 3 | B22: REGIONAL NORTE | C22: Norte | E22: =G22-F22 -> 148 | F22: =MIN(F23:F55) -> 46483 | G22: =MAX(G23:G55) -> 46631
A23: 3.1 | B23: BLOCO 1 - 4 de Araguaína IV - Instalação de 1 RL 13,8 kV (92118) | C23: Norte | D23: 92118 | E23: =G23-F23 -> 82 | F23: =MIN(F24:F33) -> 46483 | G23: =MAX(G24:G33) -> 46565 | H23: GP | K23: A iniciar
A24: 3.1.1 | B24: Executar Obras | C24: Norte | D24: 92118 | E24: 30 | F24: =G24-E24 -> 46483 | G24: =F26-1 -> 46513 | H24: EPS / Supervisor | K24: A iniciar
A25: 3.1.2 | B25: Obras Concluídas | C25: Norte | D25: 92118 | E25: 0 | F25: =G24 -> 46513 | G25: =G24 -> 46513 | H25: EPS | K25: A iniciar
A26: 3.1.3 | B26: Fiscalização | C26: Norte | D26: 92118 | E26: 12 | F26: =G26-E26 -> 46514 | G26: =F27-1 -> 46526 | H26: Fiscalização DCMD | K26: A iniciar
A27: 3.1.4 | B27: Cadastro EO / Integração parcial | C27: Norte | D27: 92118 | E27: 10 | F27: =G27-E27 -> 46527 | G27: =F30-1 -> 46537 | H27: Cadastro EO/TS | K27: A iniciar
A28: 3.1.5 | B28: Entrega do TCI pela empreiteira / Integração final | C28: Norte | D28: 92118 | E28: 15 | F28: =F30 -> 46538 | G28: =F28+E28 -> 46553 | H28: EPS | K28: A iniciar
A29: 3.1.6 | B29: Abertura de chamado / Atendimento GAT | C29: Norte | D29: 92118 | E29: 8 | F29: =F30 -> 46538 | G29: =F29+E29 -> 46546 | H29: GAT | K29: A iniciar
A30: 3.1.7 | B30: Comissionar Equipamentos | C30: Norte | D30: 92118 | E30: 15 | F30: =G30-E30 -> 46538 | G30: =F31 -> 46553 | H30: DMSL / DEOP | K30: A iniciar
A31: 3.1.8 | B31: Equipamentos em Operação | C31: Norte | D31: 92118 | E31: 0 | F31: 46553 | G31: =F31 -> 46553 | H31: DCMD | I31: 46508 | J31: =EOMONTH(I31,0)-F31 -> -15 | K31: A iniciar
A32: 3.1.9 | B32: Encerramento Técnico | C32: Norte | D32: 92118 | E32: 7 | F32: =G31+1 -> 46554 | G32: =F32+E32 -> 46561 | H32: DCMD | K32: A iniciar
A33: 3.1.10 | B33: Encerramento Contábil | C33: Norte | D33: 92118 | E33: 3 | F33: =G32+1 -> 46562 | G33: =F33+E33 -> 46565 | H33: DCMD / Contábil | K33: A iniciar
A34: 3.2 | B34: BLOCO 2 - LD Xambioá II - Araguanã - Instalação de 2 RT 34,5 kV (89267) | C34: Norte | D34: 89267 | E34: =G34-F34 -> 82 | F34: =MIN(F35:F44) -> 46483 | G34: =MAX(G35:G44) -> 46565 | H34: GP | K34: A iniciar
A35: 3.2.1 | B35: Executar Obras | C35: Norte | D35: 89267 | E35: 30 | F35: =G35-E35 -> 46483 | G35: =F37-1 -> 46513 | H35: EPS / Supervisor | K35: A iniciar
A36: 3.2.2 | B36: Obras Concluídas | C36: Norte | D36: 89267 | E36: 0 | F36: =G35 -> 46513 | G36: =G35 -> 46513 | H36: EPS | K36: A iniciar
A37: 3.2.3 | B37: Fiscalização | C37: Norte | D37: 89267 | E37: 12 | F37: =G37-E37 -> 46514 | G37: =F38-1 -> 46526 | H37: Fiscalização DCMD | K37: A iniciar
A38: 3.2.4 | B38: Cadastro EO / Integração parcial | C38: Norte | D38: 89267 | E38: 10 | F38: =G38-E38 -> 46527 | G38: =F41-1 -> 46537 | H38: Cadastro EO/TS | K38: A iniciar
A39: 3.2.5 | B39: Entrega do TCI pela empreiteira / Integração final | C39: Norte | D39: 89267 | E39: 15 | F39: =F41 -> 46538 | G39: =F39+E39 -> 46553 | H39: EPS | K39: A iniciar
A40: 3.2.6 | B40: Abertura de chamado / Atendimento GAT | C40: Norte | D40: 89267 | E40: 8 | F40: =F41 -> 46538 | G40: =F40+E40 -> 46546 | H40: GAT | K40: A iniciar
A41: 3.2.7 | B41: Comissionar Equipamentos | C41: Norte | D41: 89267 | E41: 15 | F41: =G41-E41 -> 46538 | G41: =F42 -> 46553 | H41: DMSL / DEOP | K41: A iniciar
...

Sheet Curva_Orcamentaria
A1: Curva orçamentária 2027 – por SIGCO (R$)
A2: Orçamento base 08.10 (Cadastro CAPEX 2027-2029). Distribuição em dias corridos entre o início de 'Executar Obras' e o fim da 'Fiscalização' de cada SIGCO (datas vinculadas à aba WBS_Cronograma).
H3: mês → | I3: 46388 | J3: 46419 | K3: 46447 | L3: 46478 | M3: 46508 | N3: 46539 | O3: 46569 | P3: 46600 | Q3: 46631 | R3: 46661 | S3: 46692 | T3: 46722
A4: SIGCO | B4: Projeto | C4: Regional | D4: Orçamento 08.10 (R$) | E4: Orçamento TM/ago (R$) | F4: Início janela | G4: Fim janela | H4: Dias | I4: Jan | J4: Fev | K4: Mar | L4: Abr | M4: Mai | N4: Jun | O4: Jul | P4: Ago | Q4: Set | R4: Out | S4: Nov | T4: Dez | U4: Total | V4: Check
A5: 92118 | B5: Estudo de QS - 4 de Araguaína IV | C5: Norte | D5: 110736.26 | E5: 121831.52 | F5: =MIN(WBS_Cronograma!F24) -> 46483 | G5: =MAX(WBS_Cronograma!G26) -> 46526 | H5: =G5-F5+1 -> 44 | I5: =$D5*MAX(0,MIN($G5,EOMONTH(I$3,0))-MAX($F5,I$3)+1)/$H5 -> 0 | J5: =$D5*MAX(0,MIN($G5,EOMONTH(J$3,0))-MAX($F5,J$3)+1)/$H5 -> 0 | K5: =$D5*MAX(0,MIN($G5,EOMONTH(K$3,0))-MAX($F5,K$3)+1)/$H5 -> 0 | L5: =$D5*MAX(0,MIN($G5,EOMONTH(L$3,0))-MAX($F5,L$3)+1)/$H5 -> 62918.33 | M5: =$D5*MAX(0,MIN($G5,EOMONTH(M$3,0))-MAX($F5,M$3)+1)/$H5 -> 47817.93 | N5: =$D5*MAX(0,MIN($G5,EOMONTH(N$3,0))-MAX($F5,N$3)+1)/$H5 -> 0 | O5: =$D5*MAX(0,MIN($G5,EOMONTH(O$3,0))-MAX($F5,O$3)+1)/$H5 -> 0 | P5: =$D5*MAX(0,MIN($G5,EOMONTH(P$3,0))-MAX($F5,P$3)+1)/$H5 -> 0 | ... T5: =$D5*MAX(0,MIN($G5,EOMONTH(T$3,0))-MAX($F5,T$3)+1)/$H5 -> 0 | U5: =SUM(I5:T5) -> 110736.26 | V5: =IF(ABS(U5-D5)<0.01,"OK","ERRO") -> OK
A6: 89267 | B6: Instalação de RT - LD Xambioá II - Araguanã - 2XB2 - QP | C6: Norte | D6: 802322.33 | E6: 1083084.6 | F6: =MIN(WBS_Cronograma!F35) -> 46483 | G6: =MAX(WBS_Cronograma!G37) -> 46526 | H6: =G6-F6+1 -> 44 | I6: =$D6*MAX(0,MIN($G6,EOMONTH(I$3,0))-MAX($F6,I$3)+1)/$H6 -> 0 | J6: =$D6*MAX(0,MIN($G6,EOMONTH(J$3,0))-MAX($F6,J$3)+1)/$H6 -> 0 | K6: =$D6*MAX(0,MIN($G6,EOMONTH(K$3,0))-MAX($F6,K$3)+1)/$H6 -> 0 | L6: =$D6*MAX(0,MIN($G6,EOMONTH(L$3,0))-MAX($F6,L$3)+1)/$H6 -> 455864.96 | M6: =$D6*MAX(0,MIN($G6,EOMONTH(M$3,0))-MAX($F6,M$3)+1)/$H6 -> 346457.37 | N6: =$D6*MAX(0,MIN($G6,EOMONTH(N$3,0))-MAX($F6,N$3)+1)/$H6 -> 0 | O6: =$D6*MAX(0,MIN($G6,EOMONTH(O$3,0))-MAX($F6,O$3)+1)/$H6 -> 0 | P6: =$D6*MAX(0,MIN($G6,EOMONTH(P$3,0))-MAX($F6,P$3)+1)/$H6 -> 0 | ... T6: =$D6*MAX(0,MIN($G6,EOMONTH(T$3,0))-MAX($F6,T$3)+1)/$H6 -> 0 | U6: =SUM(I6:T6) -> 802322.33 | V6: =IF(ABS(U6-D6)<0.01,"OK","ERRO") -> OK
A7: 89249 | B7: Instalação de RT - LD Araguaína - Babaçulândia - 2AR0 - QP | C7: Norte | D7: 399614.39 | E7: 539995.52 | F7: =MIN(WBS_Cronograma!F46) -> 46549 | G7: =MAX(WBS_Cronograma!G48) -> 46592 | H7: =G7-F7+1 -> 44 | I7: =$D7*MAX(0,MIN($G7,EOMONTH(I$3,0))-MAX($F7,I$3)+1)/$H7 -> 0 | J7: =$D7*MAX(0,MIN($G7,EOMONTH(J$3,0))-MAX($F7,J$3)+1)/$H7 -> 0 | K7: =$D7*MAX(0,MIN($G7,EOMONTH(K$3,0))-MAX($F7,K$3)+1)/$H7 -> 0 | L7: =$D7*MAX(0,MIN($G7,EOMONTH(L$3,0))-MAX($F7,L$3)+1)/$H7 -> 0 | M7: =$D7*MAX(0,MIN($G7,EOMONTH(M$3,0))-MAX($F7,M$3)+1)/$H7 -> 0 | N7: =$D7*MAX(0,MIN($G7,EOMONTH(N$3,0))-MAX($F7,N$3)+1)/$H7 -> 181642.9 | O7: =$D7*MAX(0,MIN($G7,EOMONTH(O$3,0))-MAX($F7,O$3)+1)/$H7 -> 217971.49 | P7: =$D7*MAX(0,MIN($G7,EOMONTH(P$3,0))-MAX($F7,P$3)+1)/$H7 -> 0 | ... T7: =$D7*MAX(0,MIN($G7,EOMONTH(T$3,0))-MAX($F7,T$3)+1)/$H7 -> 0 | U7: =SUM(I7:T7) -> 399614.39 | V7: =IF(ABS(U7-D7)<0.01,"OK","ERRO") -> OK
A8: 90811 | B8: Instalação de RL e RT - LD UHE Isamu - Ponte Alta - 1UI1 - QP | C8: Centro | D8: 1801604.8 | E8: 1627897 | F8: =MIN(WBS_Cronograma!F69,WBS_Cronograma!F80) -> 46483 | G8: =MAX(WBS_Cronograma!G71,WBS_Cronograma!G82) -> 46541 | H8: =G8-F8+1 -> 59 | I8: =$D8*MAX(0,MIN($G8,EOMONTH(I$3,0))-MAX($F8,I$3)+1)/$H8 -> 0 | J8: =$D8*MAX(0,MIN($G8,EOMONTH(J$3,0))-MAX($F8,J$3)+1)/$H8 -> 0 | K8: =$D8*MAX(0,MIN($G8,EOMONTH(K$3,0))-MAX($F8,K$3)+1)/$H8 -> 0 | L8: =$D8*MAX(0,MIN($G8,EOMONTH(L$3,0))-MAX($F8,L$3)+1)/$H8 -> 763391.87 | M8: =$D8*MAX(0,MIN($G8,EOMONTH(M$3,0))-MAX($F8,M$3)+1)/$H8 -> 946605.92 | N8: =$D8*MAX(0,MIN($G8,EOMONTH(N$3,0))-MAX($F8,N$3)+1)/$H8 -> 91607.025 | O8: =$D8*MAX(0,MIN($G8,EOMONTH(O$3,0))-MAX($F8,O$3)+1)/$H8 -> 0 | P8: =$D8*MAX(0,MIN($G8,EOMONTH(P$3,0))-MAX($F8,P$3)+1)/$H8 -> 0 | ... T8: =$D8*MAX(0,MIN($G8,EOMONTH(T$3,0))-MAX($F8,T$3)+1)/$H8 -> 0 | U8: =SUM(I8:T8) -> 1801604.8 | V8: =IF(ABS(U8-D8)<0.01,"OK","ERRO") -> OK
A9: 92095 | B9: Estudo de QS - LD Palmas - Lajeado | C9: Centro | D9: 130250.01 | E9: 168438.86 | F9: =MIN(WBS_Cronograma!F91) -> 46483 | G9: =MAX(WBS_Cronograma!G93) -> 46526 | H9: =G9-F9+1 -> 44 | I9: =$D9*MAX(0,MIN($G9,EOMONTH(I$3,0))-MAX($F9,I$3)+1)/$H9 -> 0 | J9: =$D9*MAX(0,MIN($G9,EOMONTH(J$3,0))-MAX($F9,J$3)+1)/$H9 -> 0 | K9: =$D9*MAX(0,MIN($G9,EOMONTH(K$3,0))-MAX($F9,K$3)+1)/$H9 -> 0 | L9: =$D9*MAX(0,MIN($G9,EOMONTH(L$3,0))-MAX($F9,L$3)+1)/$H9 -> 74005.688 | M9: =$D9*MAX(0,MIN($G9,EOMONTH(M$3,0))-MAX($F9,M$3)+1)/$H9 -> 56244.323 | N9: =$D9*MAX(0,MIN($G9,EOMONTH(N$3,0))-MAX($F9,N$3)+1)/$H9 -> 0 | O9: =$D9*MAX(0,MIN($G9,EOMONTH(O$3,0))-MAX($F9,O$3)+1)/$H9 -> 0 | P9: =$D9*MAX(0,MIN($G9,EOMONTH(P$3,0))-MAX($F9,P$3)+1)/$H9 -> 0 | ... T9: =$D9*MAX(0,MIN($G9,EOMONTH(T$3,0))-MAX($F9,T$3)+1)/$H9 -> 0 | U9: =SUM(I9:T9) -> 130250.01 | V9: =IF(ABS(U9-D9)<0.01,"OK","ERRO") -> OK
A10: 92101 | B10: Estudo de QS - 8 de Palmas IV | C10: Centro | D10: 110736.26 | E10: 121831.52 | F10: =MIN(WBS_Cronograma!F102) -> 46483 | G10: =MAX(WBS_Cronograma!G104) -> 46526 | H10: =G10-F10+1 -> 44 | I10: =$D10*MAX(0,MIN($G10,EOMONTH(I$3,0))-MAX($F10,I$3)+1)/$H10 -> 0 | J10: =$D10*MAX(0,MIN($G10,EOMONTH(J$3,0))-MAX($F10,J$3)+1)/$H10 -> 0 | K10: =$D10*MAX(0,MIN($G10,EOMONTH(K$3,0))-MAX($F10,K$3)+1)/$H10 -> 0 | L10: =$D10*MAX(0,MIN($G10,EOMONTH(L$3,0))-MAX($F10,L$3)+1)/$H10 -> 62918.33 | M10: =$D10*MAX(0,MIN($G10,EOMONTH(M$3,0))-MAX($F10,M$3)+1)/$H10 -> 47817.93 | N10: =$D10*MAX(0,MIN($G10,EOMONTH(N$3,0))-MAX($F10,N$3)+1)/$H10 -> 0 | O10: =$D10*MAX(0,MIN($G10,EOMONTH(O$3,0))-MAX($F10,O$3)+1)/$H10 -> 0 | P10: =$D10*MAX(0,MIN($G10,EOMONTH(P$3,0))-MAX($F10,P$3)+1)/$H10 -> 0 | ... T10: =$D10*MAX(0,MIN($G10,EOMONTH(T$3,0))-MAX($F10,T$3)+1)/$H10 -> 0 | U10: =SUM(I10:T10) -> 110736.26 | V10: =IF(ABS(U10-D10)<0.01,"OK","ERRO") -> OK
A11: 70838 | B11: Instalação de RT - LD Cristalândia - Lagoa da Confusão | C11: Centro | D11: 399614.39 | E11: 539995.52 | F11: =MIN(WBS_Cronograma!F113) -> 46483 | G11: =MAX(WBS_Cronograma!G115) -> 46526 | H11: =G11-F11+1 -> 44 | I11: =$D11*MAX(0,MIN($G11,EOMONTH(I$3,0))-MAX($F11,I$3)+1)/$H11 -> 0 | J11: =$D11*MAX(0,MIN($G11,EOMONTH(J$3,0))-MAX($F11,J$3)+1)/$H11 -> 0 | K11: =$D11*MAX(0,MIN($G11,EOMONTH(K$3,0))-MAX($F11,K$3)+1)/$H11 -> 0 | L11: =$D11*MAX(0,MIN($G11,EOMONTH(L$3,0))-MAX($F11,L$3)+1)/$H11 -> 227053.63 | M11: =$D11*MAX(0,MIN($G11,EOMONTH(M$3,0))-MAX($F11,M$3)+1)/$H11 -> 172560.76 | N11: =$D11*MAX(0,MIN($G11,EOMONTH(N$3,0))-MAX($F11,N$3)+1)/$H11 -> 0 | O11: =$D11*MAX(0,MIN($G11,EOMONTH(O$3,0))-MAX($F11,O$3)+1)/$H11 -> 0 | P11: =$D11*MAX(0,MIN($G11,EOMONTH(P$3,0))-MAX($F11,P$3)+1)/$H11 -> 0 | ... T11: =$D11*MAX(0,MIN($G11,EOMONTH(T$3,0))-MAX($F11,T$3)+1)/$H11 -> 0 | U11: =SUM(I11:T11) -> 399614.39 | V11: =IF(ABS(U11-D11)<0.01,"OK","ERRO") -> OK
A12: 92102 | B12: Estudo de QS - 6 de Palmas IV | C12: Centro | D12: 110736.26 | E12: 121831.52 | F12: =MIN(WBS_Cronograma!F124) -> 46486 | G12: =MAX(WBS_Cronograma!G126) -> 46529 | H12: =G12-F12+1 -> 44 | I12: =$D12*MAX(0,MIN($G12,EOMONTH(I$3,0))-MAX($F12,I$3)+1)/$H12 -> 0 | J12: =$D12*MAX(0,MIN($G12,EOMONTH(J$3,0))-MAX($F12,J$3)+1)/$H12 -> 0 | K12: =$D12*MAX(0,MIN($G12,EOMONTH(K$3,0))-MAX($F12,K$3)+1)/$H12 -> 0 | L12: =$D12*MAX(0,MIN($G12,EOMONTH(L$3,0))-MAX($F12,L$3)+1)/$H12 -> 55368.13 | M12: =$D12*MAX(0,MIN($G12,EOMONTH(M$3,0))-MAX($F12,M$3)+1)/$H12 -> 55368.13 | N12: =$D12*MAX(0,MIN($G12,EOMONTH(N$3,0))-MAX($F12,N$3)+1)/$H12 -> 0 | O12: =$D12*MAX(0,MIN($G12,EOMONTH(O$3,0))-MAX($F12,O$3)+1)/$H12 -> 0 | P12: =$D12*MAX(0,MIN($G12,EOMONTH(P$3,0))-MAX($F12,P$3)+1)/$H12 -> 0 | ... T12: =$D12*MAX(0,MIN($G12,EOMONTH(T$3,0))-MAX($F12,T$3)+1)/$H12 -> 0 | U12: =SUM(I12:T12) -> 110736.26 | V12: =IF(ABS(U12-D12)<0.01,"OK","ERRO") -> OK
A13: 70978 | B13: Instalação de RT e Balanceamento de Fase - LD Paraíso I - Caseara - 2PR0 - QP | C13: Centro | D13: 399913.77 | E13: 540294.9 | F13: =MIN(WBS_Cronograma!F135) -> 46486 | G13: =MAX(WBS_Cronograma!G137) -> 46529 | H13: =G13-F13+1 -> 44 | I13: =$D13*MAX(0,MIN($G13,EOMONTH(I$3,0))-MAX($F13,I$3)+1)/$H13 -> 0 | J13: =$D13*MAX(0,MIN($G13,EOMONTH(J$3,0))-MAX($F13,J$3)+1)/$H13 -> 0 | K13: =$D13*MAX(0,MIN($G13,EOMONTH(K$3,0))-MAX($F13,K$3)+1)/$H13 -> 0 | L13: =$D13*MAX(0,MIN($G13,EOMONTH(L$3,0))-MAX($F13,L$3)+1)/$H13 -> 199956.88 | M13: =$D13*MAX(0,MIN($G13,EOMONTH(M$3,0))-MAX($F13,M$3)+1)/$H13 -> 199956.88 | N13: =$D13*MAX(0,MIN($G13,EOMONTH(N$3,0))-MAX($F13,N$3)+1)/$H13 -> 0 | O13: =$D13*MAX(0,MIN($G13,EOMONTH(O$3,0))-MAX($F13,O$3)+1)/$H13 -> 0 | P13: =$D13*MAX(0,MIN($G13,EOMONTH(P$3,0))-MAX($F13,P$3)+1)/$H13 -> 0 | ... T13: =$D13*MAX(0,MIN($G13,EOMONTH(T$3,0))-MAX($F13,T$3)+1)/$H13 -> 0 | U13: =SUM(I13:T13) -> 399913.77 | V13: =IF(ABS(U13-D13)<0.01,"OK","ERRO") -> OK
A14: 92094 | B14: Estudo de QS - LD Palmas - Aparecida do Rio Negro | C14: Centro | D14: 390750.03 | E14: 505316.58 | F14: =MIN(WBS_Cronograma!F146) -> 46493 | G14: =MAX(WBS_Cronograma!G148) -> 46536 | H14: =G14-F14+1 -> 44 | I14: =$D14*MAX(0,MIN($G14,EOMONTH(I$3,0))-MAX($F14,I$3)+1)/$H14 -> 0 | J14: =$D14*MAX(0,MIN($G14,EOMONTH(J$3,0))-MAX($F14,J$3)+1)/$H14 -> 0 | K14: =$D14*MAX(0,MIN($G14,EOMONTH(K$3,0))-MAX($F14,K$3)+1)/$H14 -> 0 | L14: =$D14*MAX(0,MIN($G14,EOMONTH(L$3,0))-MAX($F14,L$3)+1)/$H14 -> 133210.24 | M14: =$D14*MAX(0,MIN($G14,EOMONTH(M$3,0))-MAX($F14,M$3)+1)/$H14 -> 257539.79 | N14: =$D14*MAX(0,MIN($G14,EOMONTH(N$3,0))-MAX($F14,N$3)+1)/$H14 -> 0 | O14: =$D14*MAX(0,MIN($G14,EOMONTH(O$3,0))-MAX($F14,O$3)+1)/$H14 -> 0 | P14: =$D14*MAX(0,MIN($G14,EOMONTH(P$3,0))-MAX($F14,P$3)+1)/$H14 -> 0 | ... T14: =$D14*MAX(0,MIN($G14,EOMONTH(T$3,0))-MAX($F14,T$3)+1)/$H14 -> 0 | U14: =SUM(I14:T14) -> 390750.03 | V14: =IF(ABS(U14-D14)<0.01,"OK","ERRO") -> OK
A15: 91979 | B15: Estudo de QS - LD Gurupi - Dueré | C15: Sul | D15: 239581.77 | E15: 275195.36 | F15: =MIN(WBS_Cronograma!F158) -> 46483 | G15: =MAX(WBS_Cronograma!G160) -> 46526 | H15: =G15-F15+1 -> 44 | I15: =$D15*MAX(0,MIN($G15,EOMONTH(I$3,0))-MAX($F15,I$3)+1)/$H15 -> 0 | J15: =$D15*MAX(0,MIN($G15,EOMONTH(J$3,0))-MAX($F15,J$3)+1)/$H15 -> 0 | K15: =$D15*MAX(0,MIN($G15,EOMONTH(K$3,0))-MAX($F15,K$3)+1)/$H15 -> 0 | L15: =$D15*MAX(0,MIN($G15,EOMONTH(L$3,0))-MAX($F15,L$3)+1)/$H15 -> 136126.01 | M15: =$D15*MAX(0,MIN($G15,EOMONTH(M$3,0))-MAX($F15,M$3)+1)/$H15 -> 103455.76 | N15: =$D15*MAX(0,MIN($G15,EOMONTH(N$3,0))-MAX($F15,N$3)+1)/$H15 -> 0 | O15: =$D15*MAX(0,MIN($G15,EOMONTH(O$3,0))-MAX($F15,O$3)+1)/$H15 -> 0 | P15: =$D15*MAX(0,MIN($G15,EOMONTH(P$3,0))-MAX($F15,P$3)+1)/$H15 -> 0 | ... T15: =$D15*MAX(0,MIN($G15,EOMONTH(T$3,0))-MAX($F15,T$3)+1)/$H15 -> 0 | U15: =SUM(I15:T15) -> 239581.77 | V15: =IF(ABS(U15-D15)<0.01,"OK","ERRO") -> OK
A16: 89307 | B16: Instalação de RT - 1 de Figueirópolis - 2FGR - QP | C16: Sul | D16: 330989.03 | E16: 373175.86 | F16: =MIN(WBS_Cronograma!F180) -> 46542 | G16: =MAX(WBS_Cronograma!G182) -> 46585 | H16: =G16-F16+1 -> 44 | I16: =$D16*MAX(0,MIN($G16,EOMONTH(I$3,0))-MAX($F16,I$3)+1)/$H16 -> 0 | J16: =$D16*MAX(0,MIN($G16,EOMONTH(J$3,0))-MAX($F16,J$3)+1)/$H16 -> 0 | K16: =$D16*MAX(0,MIN($G16,EOMONTH(K$3,0))-MAX($F16,K$3)+1)/$H16 -> 0 | L16: =$D16*MAX(0,MIN($G16,EOMONTH(L$3,0))-MAX($F16,L$3)+1)/$H16 -> 0 | M16: =$D16*MAX(0,MIN($G16,EOMONTH(M$3,0))-MAX($F16,M$3)+1)/$H16 -> 0 | N16: =$D16*MAX(0,MIN($G16,EOMONTH(N$3,0))-MAX($F16,N$3)+1)/$H16 -> 203106.91 | O16: =$D16*MAX(0,MIN($G16,EOMONTH(O$3,0))-MAX($F16,O$3)+1)/$H16 -> 127882.13 | P16: =$D16*MAX(0,MIN($G16,EOMONTH(P$3,0))-MAX($F16,P$3)+1)/$H16 -> 0 | ... T16: =$D16*MAX(0,MIN($G16,EOMONTH(T$3,0))-MAX($F16,T$3)+1)/$H16 -> 0 | U16: =SUM(I16:T16) -> 330989.03 | V16: =IF(ABS(U16-D16)<0.01,"OK","ERRO") -> OK
B17: TOTAL | D17: =SUM(D5:D16) -> 5226849.3 | E17: =SUM(E5:E16) -> 6018888.7 | I17: =SUM(I5:I16) -> 0 | J17: =SUM(J5:J16) -> 0 | K17: =SUM(K5:K16) -> 0 | L17: =SUM(L5:L16) -> 2170814.1 | M17: =SUM(M5:M16) -> 2233824.8 | N17: =SUM(N5:N16) -> 476356.84 | O17: =SUM(O5:O16) -> 345853.61 | P17: =SUM(P5:P16) -> 0 | ... U17: =SUM(U5:U16) -> 5226849.3
B18: Acumulado (R$) | I18: =SUM($I17:I17) -> 0 | J18: =SUM($I17:J17) -> 0 | K18: =SUM($I17:K17) -> 0 | L18: =SUM($I17:L17) -> 2170814.1 | M18: =SUM($I17:M17) -> 4404638.9 | N18: =SUM($I17:N17) -> 4880995.7 | O18: =SUM($I17:O17) -> 5226849.3 | P18: =SUM($I17:P17) -> 5226849.3 | ... T18: =SUM($I17:T17) -> 5226849.3
B19: Acumulado (% do orçamento 08.10) | I19: =I18/$D$17 -> 0 | J19: =J18/$D$17 -> 0 | K19: =K18/$D$17 -> 0 | L19: =L18/$D$17 -> 0.41531981 | M19: =M18/$D$17 -> 0.84269482 | N19: =N18/$D$17 -> 0.93383134 | O19: =O18/$D$17 -> 1 | P19: =P18/$D$17 -> 1 | ... T19: =T18/$D$17 -> 1
B21: Resumo por regional (R$)
B22: Norte | D22: =SUMIFS(D$5:D$16,$C$5:$C$16,"Norte") -> 1312673 | I22: =SUMIFS(I$5:I$16,$C$5:$C$16,"Norte") -> 0 | J22: =SUMIFS(J$5:J$16,$C$5:$C$16,"Norte") -> 0 | K22: =SUMIFS(K$5:K$16,$C$5:$C$16,"Norte") -> 0 | L22: =SUMIFS(L$5:L$16,$C$5:$C$16,"Norte") -> 518783.29 | M22: =SUMIFS(M$5:M$16,$C$5:$C$16,"Norte") -> 394275.3 | N22: =SUMIFS(N$5:N$16,$C$5:$C$16,"Norte") -> 181642.9 | O22: =SUMIFS(O$5:O$16,$C$5:$C$16,"Norte") -> 217971.49 | P22: =SUMIFS(P$5:P$16,$C$5:$C$16,"Norte") -> 0 | ... U22: =SUMIFS(U$5:U$16,$C$5:$C$16,"Norte") -> 1312673
B23: Centro | D23: =SUMIFS(D$5:D$16,$C$5:$C$16,"Centro") -> 3343605.5 | I23: =SUMIFS(I$5:I$16,$C$5:$C$16,"Centro") -> 0 | J23: =SUMIFS(J$5:J$16,$C$5:$C$16,"Centro") -> 0 | K23: =SUMIFS(K$5:K$16,$C$5:$C$16,"Centro") -> 0 | L23: =SUMIFS(L$5:L$16,$C$5:$C$16,"Centro") -> 1515904.8 | M23: =SUMIFS(M$5:M$16,$C$5:$C$16,"Centro") -> 1736093.7 | N23: =SUMIFS(N$5:N$16,$C$5:$C$16,"Centro") -> 91607.025 | O23: =SUMIFS(O$5:O$16,$C$5:$C$16,"Centro") -> 0 | P23: =SUMIFS(P$5:P$16,$C$5:$C$16,"Centro") -> 0 | ... U23: =SUMIFS(U$5:U$16,$C$5:$C$16,"Centro") -> 3343605.5
B24: Sul | D24: =SUMIFS(D$5:D$16,$C$5:$C$16,"Sul") -> 570570.8 | I24: =SUMIFS(I$5:I$16,$C$5:$C$16,"Sul") -> 0 | J24: =SUMIFS(J$5:J$16,$C$5:$C$16,"Sul") -> 0 | K24: =SUMIFS(K$5:K$16,$C$5:$C$16,"Sul") -> 0 | L24: =SUMIFS(L$5:L$16,$C$5:$C$16,"Sul") -> 136126.01 | M24: =SUMIFS(M$5:M$16,$C$5:$C$16,"Sul") -> 103455.76 | N24: =SUMIFS(N$5:N$16,$C$5:$C$16,"Sul") -> 203106.91 | O24: =SUMIFS(O$5:O$16,$C$5:$C$16,"Sul") -> 127882.13 | P24: =SUMIFS(P$5:P$16,$C$5:$C$16,"Sul") -> 0 | ... U24: =SUMIFS(U$5:U$16,$C$5:$C$16,"Sul") -> 570570.8

Sheet Resumo_Blocos
A1: Resumo dos blocos – marcos principais
A3: Bloco | B3: SIGCO | C3: Regional | D3: Tipo | E3: Escopo | F3: Início execução | G3: Fim execução | H3: Comissionamento | I3: Equip. em operação | J3: Energização necessária | K3: Folga (dias) | L3: Encerramento contábil | M3: Benefício (Cadastro CAPEX)
A4: B1 | B4: 92118 | C4: Norte | D4: RL | E4: 1 religador automático 13,8 kV (ID# E.O 551144) | F4: =WBS_Cronograma!F24 -> 46483 | G4: =WBS_Cronograma!G24 -> 46513 | H4: =WBS_Cronograma!F30 -> 46538 | I4: =WBS_Cronograma!F31 -> 46553 | J4: =WBS_Cronograma!I31 -> 46508 | K4: =WBS_Cronograma!J31 -> -15 | L4: =WBS_Cronograma!G33 -> 46565 | M4: DEC -0,0775 h | FEC -0,0300 (base conjunto)
A5: B2 | B5: 89267 | C5: Norte | D5: RT | E5: 2 reguladores de tensão 34,5 kV (ID# E.O 298105 e 38281041) | F5: =WBS_Cronograma!F35 -> 46483 | G5: =WBS_Cronograma!G35 -> 46513 | H5: =WBS_Cronograma!F41 -> 46538 | I5: =WBS_Cronograma!F42 -> 46553 | J5: =WBS_Cronograma!I42 -> 46508 | K5: =WBS_Cronograma!J42 -> -15 | L5: =WBS_Cronograma!G44 -> 46565 | M5: Tensão 0,929 → 0,945 pu
A6: B3 | B6: 89249 | C6: Norte | D6: RT | E6: 1 regulador de tensão 34,5 kV (ID# E.O 535352) | F6: =WBS_Cronograma!F46 -> 46549 | G6: =WBS_Cronograma!G46 -> 46579 | H6: =WBS_Cronograma!F52 -> 46604 | I6: =WBS_Cronograma!F53 -> 46619 | J6: =WBS_Cronograma!I53 -> 46600 | K6: =WBS_Cronograma!J53 -> 11 | L6: =WBS_Cronograma!G55 -> 46631 | M6: Tensão 0,921 → 0,953 pu
A7: B4 | B7: 90811 | C7: Centro | D7: RL | E7: 4 religadores 34,5 kV; 0,25 km RD MT 3#1/0 AWG; 1 poste; 2 chaves faca (NA/NF) | F7: =WBS_Cronograma!F69 -> 46483 | G7: =WBS_Cronograma!G69 -> 46528 | H7: =WBS_Cronograma!F75 -> 46553 | I7: =WBS_Cronograma!F76 -> 46568 | J7: =WBS_Cronograma!I76 -> 46478 | K7: =WBS_Cronograma!J76 -> -61 | L7: =WBS_Cronograma!G78 -> 46580 | M7: Tensão 0,91 → 0,95 pu
A8: B5 | B8: 90811 | C8: Centro | D8: RT | E8: 3 reguladores de tensão 34,5 kV (ID# E.O 33356216, 498478 e CH 8810033256) | F8: =WBS_Cronograma!F80 -> 46483 | G8: =WBS_Cronograma!G80 -> 46513 | H8: =WBS_Cronograma!F86 -> 46538 | I8: =WBS_Cronograma!F87 -> 46553 | J8: =WBS_Cronograma!I87 -> 46478 | K8: =WBS_Cronograma!J87 -> -46 | L8: =WBS_Cronograma!G89 -> 46565 | M8: Tensão 0,91 → 0,95 pu
A9: B6 | B9: 92095 | C9: Centro | D9: RL | E9: 1 religador automático 34,5 kV (ID# E.O 425776) | F9: =WBS_Cronograma!F91 -> 46483 | G9: =WBS_Cronograma!G91 -> 46513 | H9: =WBS_Cronograma!F97 -> 46538 | I9: =WBS_Cronograma!F98 -> 46553 | J9: =WBS_Cronograma!I98 -> 46539 | K9: =WBS_Cronograma!J98 -> 15 | L9: =WBS_Cronograma!G100 -> 46565 | M9: DEC -0,3251 h | FEC -0,0694 (base conjunto)
A10: B7 | B10: 92101 | C10: Centro | D10: RL | E10: 1 religador automático 13,8 kV N.A (CH 8861680122) | F10: =WBS_Cronograma!F102 -> 46483 | G10: =WBS_Cronograma!G102 -> 46513 | H10: =WBS_Cronograma!F108 -> 46538 | I10: =WBS_Cronograma!F109 -> 46553 | J10: =WBS_Cronograma!I109 -> 46539 | K10: =WBS_Cronograma!J109 -> 15 | L10: =WBS_Cronograma!G111 -> 46565 | M10: DEC -0,1405 h | FEC -0,0756 (base conjunto)
A11: B8 | B11: 70838 | C11: Centro | D11: RT | E11: 1 regulador de tensão 34,5 kV (ID# E.O 740431) | F11: =WBS_Cronograma!F113 -> 46483 | G11: =WBS_Cronograma!G113 -> 46513 | H11: =WBS_Cronograma!F119 -> 46538 | I11: =WBS_Cronograma!F120 -> 46553 | J11: =WBS_Cronograma!I120 -> 46539 | K11: =WBS_Cronograma!J120 -> 15 | L11: =WBS_Cronograma!G122 -> 46565 | M11: Tensão 0,91 → 0,96 pu
A12: B9 | B12: 92102 | C12: Centro | D12: RL | E12: 1 religador automático 13,8 kV N.F (CH 8803933122) | F12: =WBS_Cronograma!F124 -> 46486 | G12: =WBS_Cronograma!G124 -> 46516 | H12: =WBS_Cronograma!F130 -> 46541 | I12: =WBS_Cronograma!F131 -> 46556 | J12: =WBS_Cronograma!I131 -> 46539 | K12: =WBS_Cronograma!J131 -> 12 | L12: =WBS_Cronograma!G133 -> 46568 | M12: DEC -0,0430 h | FEC -0,0174 (base conjunto)
A13: B10 | B13: 70978 | C13: Centro | D13: RT | E13: 1 regulador de tensão 34,5 kV; troca de fase (A→C) em 3 ramais | F13: =WBS_Cronograma!F135 -> 46486 | G13: =WBS_Cronograma!G135 -> 46516 | H13: =WBS_Cronograma!F141 -> 46541 | I13: =WBS_Cronograma!F142 -> 46556 | J13: =WBS_Cronograma!I142 -> 46539 | K13: =WBS_Cronograma!J142 -> 12 | L13: =WBS_Cronograma!G144 -> 46568 | M13: Tensão 0,91 → 0,97 pu
A14: B11 | B14: 92094 | C14: Centro | D14: RL | E14: 3 religadores automáticos 34,5 kV (CH 8800756083, 8841714092 e ID# E.O 49973587) | F14: =WBS_Cronograma!F146 -> 46493 | G14: =WBS_Cronograma!G146 -> 46523 | H14: =WBS_Cronograma!F152 -> 46548 | I14: =WBS_Cronograma!F153 -> 46563 | J14: =WBS_Cronograma!I153 -> 46539 | K14: =WBS_Cronograma!J153 -> 5 | L14: =WBS_Cronograma!G155 -> 46575 | M14: DEC -0,4015 h | FEC -0,2040 (base conjunto)
A15: B12 | B15: 91979 | C15: Sul | D15: RL | E15: 1 religador rural 34,5 kV (CH 3300246076); 3 TripSavers | F15: =WBS_Cronograma!F158 -> 46483 | G15: =WBS_Cronograma!G158 -> 46513 | H15: =WBS_Cronograma!F164 -> 46538 | I15: =WBS_Cronograma!F165 -> 46553 | J15: =WBS_Cronograma!I165 -> 46508 | K15: =WBS_Cronograma!J165 -> -15 | L15: =WBS_Cronograma!G167 -> 46565 | M15: DEC -0,5568 h | FEC -0,1037 (base conjunto)
A16: B13 | B16: 89307 | C16: Sul | D16: RT | E16: 1 regulador de tensão 13,8 kV (EO 241355); remanejamento do RL 7924620047; manobras | F16: =WBS_Cronograma!F180 -> 46542 | G16: =WBS_Cronograma!G180 -> 46572 | H16: =WBS_Cronograma!F186 -> 46597 | I16: =WBS_Cronograma!F187 -> 46612 | J16: =WBS_Cronograma!I187 -> 46600 | K16: =WBS_Cronograma!J187 -> 18 | L16: =WBS_Cronograma!G189 -> 46624 | M16: Tensão 0,92 → 0,96 pu

Sheet Premissas_Fontes
A1: Fontes
A2: Cadastro CAPEX 2027-2029 (24/08/2026, PMO 3.2.1) – aba 'Base 2027-2028 28.08 (2)': escopo detalhado, GP, energização e orçamento (colunas Orçamento Agosto e Orçamento 08.10).
A3: Transfer Meeting Ciclo 2027-2028 e ATA TM CAPEX 06/10/2026: energizações por SIGCO, calendário TM 06/10 · KOM 29/10 · PRM 02/12/2026.
A4: Fichas 2027 (12 SIGCOs): escopo físico e localização dos equipamentos.
A5: KOM/PRM 2026 – Obras Distribuição Regionais Centro, Norte e Sul: estrutura e durações dos blocos de equipamentos especiais.
A7: Premissas de planejamento
A8: 1. Cronograma considera somente os blocos de instalação de equipamentos especiais (RL, RT, TripSaver); não há BC nesta carteira. Gerenciamento (PMBOK) e planejamento/suprimentos constam da WBS apenas como marcos e atividades de apoio.
A9: 2. Dias corridos; término = início + duração; tarefa seguinte inicia no dia seguinte ao término da predecessora.
A10: 3. Data-alvo de 'Equipamentos em Operação' dentro do mês de energização necessária (ASPO), com folga até o fim do mês.
A11: 4. SIGCO 90811 dividido em dois blocos (Parte I – 4 RL + rede/chaves; Parte II – 3 RT).
A12: 5. Equipamentos (RL/RT/TripSaver) disponíveis somente após 05/04/2027: nenhuma execução de bloco inicia antes de 06/04/2027 (Lote 1 recebido em 05/04/2027; Lote 2 – B3 e B13 – recebido 7 dias antes do início); O.S. da EPS emitida nos 5 dias que antecedem o início de cada lote.
A13: 6. Curva orçamentária: orçamento 08.10 distribuído em dias corridos entre o início da execução e o fim da fiscalização de cada SIGCO.
... A15: 8. Orçamento a ser atualizado quando a ASPO repassar a base fechada após capitalização (ATA TM, item 1c).
